Workbook
Name 입력조건: #REF!
Name 입력조건: #REF!
Name 입력조건: #REF!
Name 입력조건: #REF!
Name 입력조건: #REF!
Name 입력조건: #REF!
Name 입력조건: #REF!
Name 입력조건: #REF!
Name 입력조건: #REF!
Name 입력조건: #REF!
Name 입력조건: #REF!
Name 입력조건: #REF!
Name 입력조건: #REF!
Name 입력조건: #REF!
Name 입력조건: #REF!
Name 입력조건: #REF!
Name 입력조건: #REF!
Name 입력조건: #REF!
Name 입력조건: #REF!
Name 판정기준: #REF!
Name 판정기준: #REF!
Name 판정기준: #REF!
Name 판정기준: #REF!
Name 판정기준: #REF!
Name 판정기준: #REF!
Name 판정기준: #REF!
Name 판정기준: #REF!
Name 판정기준: #REF!
Name 판정기준: #REF!
Name 판정기준: #REF!
Name 판정기준: #REF!
Name 판정기준: #REF!
Name 판정기준: #REF!
Name 판정기준: #REF!
Name 판정기준: #REF!
Name 판정기준: #REF!
Name 판정기준: #REF!
Name 판정기준: #REF!
Name 항목: #REF!
Name 항목: #REF!
Name 항목: #REF!
Name 항목: #REF!
Name 항목: #REF!
Name 항목: #REF!
Name 항목: #REF!
Name 항목: #REF!
Name 항목: #REF!
Name 항목: #REF!
Name 항목: #REF!
Name 항목: #REF!
Name 항목: #REF!
Name 항목: #REF!
Name 항목: #REF!
Name 항목: #REF!
Name 항목: #REF!
Name 항목: #REF!
Name 항목: #REF!

Sheet HISTORY
A1: TestCase 변경 HISTORY | L1: 품명: BLTN_CAM
L2: 제정일자 2021- -
A3: Rev | B3: 구분 | C3: 탭 | D3: TC ID | E3: 항목 | F3: 내용 | G3: 사양구분 | H3: 사유 | I3: LCR No | J3: 적용 일자 | K3: 작성자 | L3: 자동화 동기화 여부
A4: 0 | B4: 최초작성 시작 | C4: - | E4: - | F4: - | H4: - | J4: 2021-10-13
A5: Ex) 2504_04 | B5: 추가 | C5: 저장메모리 및 파일관리 | D5: MEM_038 | E5: [SD카드 사용자 조건] (1) | F5: 녹화 파일 전/후방 영상 중 하나 삭제 시 영향성 확인 | J5: 46153 | K5: 장빈 | L5: X
B6: 수정 | C6: 보조배터리 연동기능 | D6: BAT_056 | E6: [M-LBM 적용 차종] 녹화 동작 사양 -2 | F6: 모션 녹화 120시간 5% 허용오차 내용 추가 | L6: X
A7: 260527 | B7: 추가 | C7: 주행 중 녹화 기능 | D7: OWD_003, OWD_005, OWD_007, OWD_011, OWD_019, OWD_025 | E7: 3세대 4CH 관련 해상도 및 저장공간 관련 사양 변경, 소모 전력 값 변경 | F7: ※ 세부 내용은 관련 TC에 기입 4CH 관련 해상도 및 저장공간 관련 사양 변경 - 전,후방 카메라 3840 x 2160 @ 30FPS - 측방 카메라(3M) 1280 x 1440 @ 30FPS - 썸네일 해상도 전,후방 640 x 360 90kbyte 이하 - 썸네일 해상도 좌,우축방 320 * 360 90kbyte 이하 소모전력 - 주행 상시 : 2CH 10W이하, 4CH 13W 이하 - 주차 상시 : 2CH 7.5W이하, 4CH 9W 이하 | J7: 46169 | K7: 장빈 | L7: X
C8: 주차 후 녹화 기능 | D8: OWP_002, OWP_003, OWP_005, OWP_007, OWP_011, OWP_014, OWP_017, OWP_020, OWP_023 | L8: X
C9: HU연동기능 | D9: HU_007 | L9: X
C10: 모바일 앱 연동기능 | D10: APP_010,APP_011, APP_012 | L10: X
C11: 표시 관련 서비스 | D11: IND_001 | L11: X
C12: 커넥티드 관련 서비스 | D12: CCS_011 | L12: X
C13: 차량정보 저장기능 | D13: INF_001 | L13: X
C14: 파일 재생 및 편집 | D14: FIL_009 | L14: X
C15: 저장메모리 및 파일관리 | D15: MEM_005 , MEM_006 MEM_009 , MEM_010 | L15: X
C16: 동작성능 | D16: PER_001, PER_012 | L16: X

Sheet 표지
D1: 기능 검증 보고서 | J1: 작 성 | L1: 검 토 | N1: 승 인
A4: 문서 번호 | C4: 2.5세대 플랫폼 23.25.A0.11.03 기능 검증 | H4: 검증 목적 | J4: 플랫폼 개정 사양에 대한 기능 정합성 및 동작 유효성 검증
A5: 품 명 | C5: 빌트인캠 2.5세대 | H5: 기 간 | J5: 2026
A6: 참조 스펙 | C6: 01_System_Spec_BLTN_CAM_v2_4(20260115).docx | H6: 담 당
A7: 플랫폼 Ver. | C7: 23.25.A0.11.03
A8: CAN DB Ver. | C8: 20230523_STD_DB_CAR_2021_HS_B2_v23.05.01.dbc | H8: LIN DB Ver. | J8: P-LBM_LIN_DB_A_01.ldf
B9: 차종 | C9: 이벤트 | D9: HU 타입 | E9: HU Ver. | G9: 주차 전원 | H9: H/W Ver. | J9: 진단/OTA | M9: 이더넷 속도
A10: 1 | B10: JK1 PE RUS | D10: ccIC | E10: JX1PE.KOR.ccNC.000.605.230831 | H10: 1.00
A11: 2
A15: No | B15: 항목 | G15: 총 TC 수 | H15: 실행 TC 수 | I15: 결과 | K15: 판정 | L15: 개선 검증 | M15: 비고
I16: 적합 | J16: 부적합
A17: 1 | B17: 녹화 제어 | C17: 주행 중 녹화 관련 기능 | G17: =COUNT('주행 중 녹화 기능'!C:C) -> 387 | H17: =SUM(I17:J17) -> 153 | I17: =COUNTIF('주행 중 녹화 기능'!J:J,"Pass") -> 153 | J17: =COUNTIF('주행 중 녹화 기능'!J:J,"Fail") -> 0 | K17: Fail | L17: Pass | M17: 23.25.A0.11.03 #2 개선확인
A18: 2 | C18: 주차 녹화 관련 기능 | G18: =COUNT('주차 후 녹화 기능'!C:C) -> 297 | H18: =SUM(I18:J18) -> 105 | I18: =COUNTIF('주차 후 녹화 기능'!J:J,"Pass") -> 105 | J18: =COUNTIF('주차 후 녹화 기능'!J:J,"Fail") -> 0 | K18: Pass | L18: -
A19: 3 | B19: 연동 제어 | C19: 헤드 유닛 연동 기능 | G19: =COUNT('HU 연동기능'!C:C) -> 331 | H19: =SUM(I19:J19) -> 138 | I19: =COUNTIF('HU 연동기능'!J:J,"Pass") -> 138 | J19: =COUNTIF('HU 연동기능'!J:J,"Fail") -> 0 | K19: Pass | L19: -
A20: 4 | C20: 보조배터리 소모 전력 및 연동 기능 | G20: =COUNT('보조배터리 연동기능'!C:C) -> 480 | H20: =SUM(I20:J20) -> 75 | I20: =COUNTIF('보조배터리 연동기능'!J:J,"Pass") -> 75 | J20: =COUNTIF('보조배터리 연동기능'!J:J,"Fail") -> 0 | K20: Pass | L20: -
A21: 5 | C21: WiFi 연결 및 모바일 앱 연동 기능 | G21: =COUNT('모바일 앱 연동기능'!C:C) -> 115 | H21: =SUM(I21:J21) -> 0 | I21: =COUNTIF('모바일 앱 연동기능'!J:J,"Pass") -> 0 | J21: =COUNTIF('모바일 앱 연동기능'!J:J,"Fail") -> 0 | K21: Pass | L21: -
A22: 6 | C22: DCM 연동 기능 | G22: =COUNT('DCM 연동기능'!D:D) -> 732 | H22: =SUM(I22:J22) -> 0 | I22: =COUNTIF('DCM 연동기능'!O:O,"Pass") -> 0 | J22: =COUNTIF('DCM 연동기능'!O:O,"Fail") -> 0 | K22: Pass | L22: -
A23: 7 | B23: 서비스 제어 | C23: 빌트인캠 상태 정보 표시 관련 기능 | G23: =COUNT('표시 관련 서비스'!C:C) -> 109 | H23: =SUM(I23:J23) -> 48 | I23: =COUNTIF('표시 관련 서비스'!J:J,"Pass") -> 48 | J23: =COUNTIF('표시 관련 서비스'!J:J,"Fail") -> 0 | K23: Pass | L23: -
A24: 8 | C24: 커넥티드 관련 빌트인캠 상태 알림 관련 기능 | G24: =COUNT('커넥티드 관련 서비스'!C:C) -> 153 | H24: =SUM(I24:J24) -> 112 | I24: =COUNTIF('커넥티드 관련 서비스'!J:J,"Pass") -> 112 | J24: =COUNTIF('커넥티드 관련 서비스'!J:J,"Fail") -> 0 | K24: Pass | L24: -
A25: 9 | B25: 기타 제어 | C25: 주행 중 차량정보(메타데이터) 저장 기능 | G25: =COUNT('차량정보 저장기능'!C:C) -> 249 | H25: =SUM(I25:J25) -> 12 | I25: =COUNTIF('차량정보 저장기능'!J:J,"Pass") -> 12 | J25: =COUNTIF('차량정보 저장기능'!J:J,"Fail") -> 0 | K25: Pass | L25: -
A26: 10 | C26: 녹화 영상 및 소리 재생 및 편집 기능 | G26: =COUNT('파일 재생 및 편집'!C:C) -> 88 | H26: =SUM(I26:J26) -> 0 | I26: =COUNTIF('파일 재생 및 편집'!J:J,"Pass") -> 0 | J26: =COUNTIF('파일 재생 및 편집'!J:J,"Fail") -> 0 | K26: Pass | L26: -
A27: 11 | C27: 녹화 파일 정보 및 SD 카드 사양 확인 | G27: =COUNT('저장메모리 및 파일관리'!C:C) -> 410 | H27: =SUM(I27:J27) -> 0 | I27: =COUNTIF('저장메모리 및 파일관리'!J:J,"Pass") -> 0 | J27: =COUNTIF('저장메모리 및 파일관리'!J:J,"Fail") -> 0 | K27: Pass | L27: -
A28: 12 | C28: 실시간 영상 출력, 차량 모드, 업데이트 외 | G28: =COUNT('녹화 외 기본기능'!C:C) -> 116 | H28: =SUM(I28:J28) -> 25 | I28: =COUNTIF('녹화 외 기본기능'!J:J,"Pass") -> 25 | J28: =COUNTIF('녹화 외 기본기능'!J:J,"Fail") -> 0 | K28: Pass | L28: -
A29: 13 | B29: 동작 성능 | C29: 동작 성능 | G29: =COUNT('동작 성능'!C:C) -> 275 | H29: =SUM(I29:J29) -> 116 | I29: =COUNTIF('동작 성능'!J:J,"Pass") -> 116 | J29: =COUNTIF('동작 성능'!J:J,"Fail") -> 0 | K29: Pass | L29: -
A30: 14 | C30: 전기적 성능, 네트워크 동작 사양, 통신 정합성 외 | G30: =COUNT('비기능 외'!C:C) -> 313 | H30: =SUM(I30:J30) -> 196 | I30: =COUNTIF('비기능 외'!J:J,"Pass") -> 196 | J30: =COUNTIF('비기능 외'!J:J,"Fail") -> 0 | K30: Pass | L30: -
A31: 15 | B31: 진단 서비스 | C31: 고장진단, I/O Control 및 ERT기능 | G31: =COUNT('진단서비스 (1)'!C:C) -> 474 | H31: =SUM(I31:J31) -> 284 | I31: =COUNTIF('진단서비스 (1)'!J:J,"Pass") -> 284 | J31: =COUNTIF('진단서비스 (1)'!J:J,"Fail") -> 0 | K31: Pass | L31: -
A32: 16 | C32: ECU Identification 외 | G32: =COUNT('진단서비스 (2)'!C:C) -> 902 | H32: =SUM(I32:J32) -> 901 | I32: =COUNTIF('진단서비스 (2)'!J:J,"Pass") -> 901 | J32: =COUNTIF('진단서비스 (2)'!J:J,"Fail") -> 0 | K32: Pass | L32: -
A33: 17 | C33: Session, Communication Control 외 | G33: =COUNT('진단서비스 (3)'!C:C) -> 1499 | H33: =SUM(I33:J33) -> 1498 | I33: =COUNTIF('진단서비스 (3)'!J:J,"Pass") -> 1498 | J33: =COUNTIF('진단서비스 (3)'!J:J,"Fail") -> 0 | K33: Pass | L33: -
A34: Total | G34: =SUM(G17:G33) -> 6930 | H34: =SUM(H17:H33) -> 3663 | I34: =SUM(I17:I33) -> 3663 | J34: =SUM(J17:J33) -> 0 | K34: Pass
A35: ■ 부적합 개선 항목 1. 2. ■ 부적합 현황 1. 2. ■ 미검증 항목 1. 2. ※ 지역별 사양 1. 내수 - 2. 북미 - 3. 유럽 -

Sheet 매크로 실행
B2: 1. 자동화 검증 결과 | J2: 2. 사양 필터링 | M2: 3. 송부본 만들기
J11: 사양 선택
J12: 주차녹화_미지원
J16: 사양구분
J17: CAN사양_CAN
J18: CAN사양_CANFD
J19: 모션감지_지원
J20: OTA_HU기반
J21: OTA_CCU기반
J22: 주차녹화 전원_보조배터리
J23: 주차녹화 전원_eAGM
J24: 주차녹화 전원_LFP
J25: 주차녹화 전원_eAGM_PLBM
... J33: DCM_연동_SBCM X

Sheet 매크로 사용법
B2: 1. 매크로 기능 활성화
B45: 2. 매크로 기능 사용하기
B77: 3. 매크로 함수 수정
B78: 송부용으로 만들기 : 송부본 만들 시 사용되는 각 함수 포함
B79: 표지에있는매크로버튼 : 송부용_만들기 / 선택한사양_제외하기 / 자동화_풀검증 / 자동화_기본 검증
B80: ※ [송부용으로 만들기] 모듈에서 함수 추가 시에는 [표지에있는매크로버튼] 모듈에서 [송부용_만들기] 함수에서 Call 명령어로 함수 불러와야함

Sheet 테스트케이스 작성 주의사항
B4: 1. 엑셀 시트 이름/띄어쓰기 변경 하지 말것
B5: ※ 엑셀 시트 이름/띄어쓰기 OR 시트 추가 시에는 매크로 수정 필요
B8: 2. 열 삭제/추가 변경하지 말 것
B9: ※ 변경 시, 매크로 수정 필요
B12: 3. 2행에 있는 이름/띄어쓰기 변경 하지 말것
B13: ※ 변경 시, 매크로 수정필요
B16: <<신규 테스트 케이스 작성 주의 사항>>
B18: 1. 기존의 작성된 TC ID는 수정하지 말 것
B19: ※ 추적성 꺠짐 (ALM)
B21: 2. B1에 현재 작성된 TC ID 중 제일 큰 값 확인할 수 있으며, 해당 값 보다 증가하여 TC ID 부여할 것
B39: 3. Step 비어있는 값 없도록 확인할 것
B41: 4. 사양 구분 확인 할것
B42: ※ 신규 사양 구분 카테고리면 매크로 실행 탭에서 수정할 것

Sheet 주행 중 녹화 기능
A1: English Translation | B1: {="OWD_"&TEXT(MAX(IFERROR(--MID($B$2:$B$5006,5,3),0)),"000")} -> OWD_051 | D1: English Translation | E1: English Translation | H1: English Translation | I1: English Translation
A2: memo | B2: ID | C2: Step | D2: Verification items | E2: detail | F2: 전압 | G2: 전원 | H2: Execution Procedure | I2: Expected value | J2: 결과 | K2: 측정값 | L2: 비고 | N2: 매뉴얼 기본 | O2: 자동화 기본 | P2: 자동화 반영 | Q2: 사양구분 | R2: 과거차문제
A3: [BLTN_CAM-Function-001] Continuous Recording While Driving
A4: Check initial values ​​for continuous driving recording settings | B4: OWD_001 | C4: 1 | D4: [Continuous recording while driving] - (1) | E4: Check initial values ​​for continuous driving recording settings | F4: 12 V | G4: IGN | H4: ▪ ICUPowerAutoCutModesta = 0x0(Factory mode) → 0x2(Customer mode) ▪ Built-in Cam Main Screen ▪ [ccNC Settings] - [General] - [Reset] - [Delete Guest Profile / Reset System] - Check Default Values | I4: ▪ BLTN_CAM_RecSet_OWD = 0x1(OFF) : Initial value to OFF after changing from Factory mode to Customer mode | J4: Pass | N4: O | P4: O
C5: 2 | H5: ▪ Turn on Parking Continuous Recording (to check the initial value after FRS setup) ▪ [ccNC Settings] - [General] - [Reset] - [Delete Guest Profile / Reset System] | I5: ▪ Domestic/Japan/North America/Russia/Middle East BLTN_CAM_RecSet_OWD = 0x2(ON) : The default recording setting is ON when initialized after FRS setup operation ▪ Europe BLTN_CAM_RecSet_OWD = 0x1(OFF) : The default recording setting is OFF when initialized after FRS setup operation | J5: Pass | N5: O | P5: O
A6: Confirmation that continuous driving recording is not working in BLTN_CAM mode | B6: OWD_002 | C6: 1 | D6: [Continuous Recording While Driving] - (2) | E6: Confirmation that continuous driving recording is not working in BLTN_CAM mode | F6: 12 V | G6: IGN | H6: ▪ Check recording status signal | I6: ▪ BLTN_CAM_RecSta_OWD = 0x0(OFF) | J6: Pass | N6: O | O6: O | P6: O
C7: 2 | H7: ▪ Check front/rear camera indicator | I7: ▪ F/R-CAM_INDI = OFF | N7: O | O7: X | P7: X
C8: 3 | H8: ▪ Check EVENT_SW_INDI | I8: ▪ EVENT_SW_INDI = OFF | J8: Pass | N8: O | O8: O | P8: O
C9: 4 | E9: Confirmed non-operation of continuous driving recording in Engineer mode | F9: 12 V | G9: IGN | H9: ▪ Check recording status signal | I9: ▪ BLTN_CAM_RecSta_OWD = 0x0(OFF) | J9: Pass | O9: O | P9: O
C10: 5 | H10: ▪ Check front/rear camera indicator | I10: ▪ F/R-CAM_INDI = OFF | O10: X | P10: X
C11: 6 | H11: ▪ Check EVENT_SW_INDI | I11: ▪ EVENT_SW_INDI = OFF | J11: Pass | O11: O | P11: O
C12: 7 | E12: Check recording operation in AVN mode (IGN power) | F12: 12 V | G12: IGN | H12: ▪ Switch AVN screen ▪ Check recording status signal | I12: ▪ BLTN_CAM_RecSta_OWD = 0x1(Recoreding) ※ The signal delay between the actual recording time and the actual recording time will be 1 second. | J12: Pass | N12: O | O12: O | P12: O
C13: 8 | H13: ▪ Check the time taken to start recording (In Built-in Cam mode, the time is measured by the stopwatch as soon as the HOME button is pressed, and recorded as the time captured in the recording file) | I13: ▪ Recording starts within 4 seconds of exiting Built-in Cam mode | N13: O | O13: X | P13: X
C14: 9 | H14: ▪ Check front/rear camera indicator | I14: ▪ F/R-CAM_INDI = Blink - Blink Frequency: 0.5Hz(Duty : 50%) | N14: O | O14: X | P14: X
C15: 10 | H15: ▪ Check EVENT_SW_INDI | I15: ▪ EVENT_SW_INDI = ON | J15: Pass | N15: O | O15: O | P15: O
C16: 11 | E16: Check recording operation in AVN mode (ACC power) | F16: 12 V | G16: ACC | H16: ▪ Enter Built-in Cam Mode, stop recording, and exit. ▪ Check recording status signal. | I16: ▪ BLTN_CAM_RecSta_OWD = 0x1(Recoreding) | J16: Pass | N16: O | O16: O | P16: O
C17: 12 | H17: ▪ Check the time taken to start recording (In Built-in Cam mode, the time is measured by the stopwatch as soon as the HOME button is pressed, and recorded as the time captured in the recording file) | I17: ▪ Recording starts within 4 seconds of exiting Built-in Cam mode | N17: O | O17: X | P17: X
C18: 13 | H18: ▪ Check front/rear camera indicator | I18: ▪ F/R-CAM_INDI = Flash - Flash Frequency: 0.5Hz (Flash Duty: 50%) | N18: O | O18: X | P18: X
C19: 14 | H19: ▪ Check EVENT_SW_INDI | I19: ▪ EVENT_SW_INDI = ON | J19: Pass | N19: O | O19: O | P19: O
A20: Check Performance Recording Status Initial Value Performance recording applies only to specialized vehicle specifications. (CE1 KN) | B20: OWD_034 | C20: 1 | D20: [Performance Recording] - (1) | E20: Check Performance Recording Signal Initial Value | H20: ▪ ICUPowerAutoCutMode = 0x0(Factory mode) → 0x2(Customer mode) ▪ Built-in Cam Main Screen ▪ [ccNC Settings] - [General] - [Reset] - [Delete Guest Profile / Reset System] - Check Default Values | I20: ▪ BLTN_CAM_RecSta_BPR = 0x1(OFF) | P20: X | Q20: 퍼포먼스_지원
A21: Verification of Performance Recording operation and Verification of non-operation in BLTN_CAM Performance recording applies only to specialized vehicle specifications. (CE1 KN) | B21: OWD_035 | C21: 1 | D21: [Performance Recording] - (2) | E21: Verify performance recording operation in N mode | F21: 12V | G21: IGN | H21: ▪ Enter N Mode in AVN ▪ Touch N Race Cam "REC" to start recording ▪ Check Performance Recording Status Signal | I21: ▪ BLTN_CAM_RecSta_BPR = 0x1 (Recording) | P21: X | Q21: 퍼포먼스_지원
C22: 2 | H22: ▪ Check front/rear camera indicator | I22: ▪ F-CAM_INDI = ON, R-CAM_INDI = ON - Flashing Frequency: 0.5Hz (Duty : 50%) | P22: X | Q22: 퍼포먼스_지원
C23: 3 | H23: ▪ Check EVENT_SW_INDI | I23: ▪ EVENT_SW_INDI = ON | P23: X | Q23: 퍼포먼스_지원
C24: 4 | E24: Check recording status in the N Race Cam item of Performance Options. | F24: 12V | G24: IGN | H24: ▪ Performance recording in progress ▪ Enter Performance Options ▪ Check recording status of N Race Cam "REC" button among the items | I24: ▪ Performance recording proceeds without interruption (Recording count confirmed and recording indicator red confirmed) | P24: X | Q24: 퍼포먼스_지원
C25: 5 | H25: ▪ Check front/rear camera indicator | I25: ▪ F-CAM_INDI = ON, R-CAM_INDI = ON - Flashing Frequency: 0.5Hz (Duty : 50%) | P25: X | Q25: 퍼포먼스_지원
C26: 6 | H26: ▪ Check EVENT_SW_INDI | I26: ▪ EVENT_SW_INDI = ON | P26: X | Q26: 퍼포먼스_지원
C27: 7 | E27: Check recording status in the N Race Cam item of Performance Options. | F27: 12V | G27: IGN | H27: ▪ Performance recording in progress ▪ Enter Performance Options ▪ Touch the N Race Cam "File" button among the items | I27: ▪ Go to Built-in Cam Video Save List After Performance Ends | P27: X | Q27: 퍼포먼스_지원
C28: 8 | H28: ▪ Check front/rear camera indicator | I28: ▪ F/RCAM_INDI =OFF | P28: X | Q28: 퍼포먼스_지원
C29: 9 | H29: ▪ Check EVENT_SW_INDI | I29: ▪ EVENT_SW_INDI = ON | P29: X | Q29: 퍼포먼스_지원
C30: 10 | E30: Verify recording operation in AVN mode | F30: 12 V | G30: IGN | H30: ▪ Start Performance Recording ▪ Switch from N Mode to AVN Screen ▪ Check Recording Status Signal | I30: ▪ BLTN_CAM_RecSta_BPR = 0x1 (Recording) | P30: X | Q30: 퍼포먼스_지원
C31: 11 | H31: ▪ Check front/rear camera indicator | I31: ▪ F-CAM_INDI = ON, R-CAM_INDI = ON - Flashing Frequency: 0.5Hz (Duty : 50%) | P31: X | Q31: 퍼포먼스_지원
C32: 12 | H32: ▪ Check EVENT_SW_INDI | I32: ▪ EVENT_SW_INDI = ON | P32: X | Q32: 퍼포먼스_지원
C33: 13 | H33: ▪ Check the indicator on the display | I33: ▪ Indicator displayed during recording | P33: X | Q33: 퍼포먼스_지원
C34: 14 | E34: Confirmation of non-operation of performance recording in BLTN_CAM mode | F34: 12V | G34: IGN | H34: ▪ Start performance recording ▪ Enter built-in cam ▪ Check recording status signal | I34: ▪ BLTN_CAM_RecSta_BPR = 0x0 (OFF) | P34: X | Q34: 퍼포먼스_지원
C35: 15 | H35: ▪ Check front/rear camera indicator | I35: ▪ F/R-CAM_INDI = OFF | P35: X | Q35: 퍼포먼스_지원
C36: 16 | H36: ▪ Check EVENT_SW_INDI | I36: ▪ EVENT_SW_INDI = OFF | P36: X | Q36: 퍼포먼스_지원
C37: 17 | H37: ▪ Check the indicator on the display | I37: ▪ Indicator not showing recording | P37: X | Q37: 퍼포먼스_지원
A38: Confirm recording file creation (3 minutes) - Create 3 1-minute recording files | B38: OWD_003 | C38: 1 | D38: [Continuous Recording While Driving] - (3) | E38: Confirm recording file creation (3 minutes) - Create 3 1-minute recording files | F38: 12 V | G38: IGN | H38: ▪ 3-Minute Standby ▪ Built-in Cam Main Screen ▪ [Always On While Driving] Check Storage Box | I38: ▪ Thumbnail and video name (date and time) should be verified correctly. ▪ Four videos (Front + Rear + Side - 60 sec) should be combined and displayed as a single group. | O38: X | P38: X
C39: 2 | H39: ▪ Play generated recording file | I39: ▪ There should be no issues with video tearing, black screens, noise, or video color. | O39: X | P39: X
C40: 3 | E40: Check recording file specifications | F40: 12 V | G40: IGN | H40: ▪ Check the generated recording file on the PC | I40: ▪ Video saving/playback frame rate 30 FPS | N40: O | O40: X | P40: X
...

Sheet 주차 후 녹화 기능
A1: English Translation | B1: {="OWP_"&TEXT(MAX(IFERROR(--MID($B$2:$B$5010,5,3),0)),"000")} -> OWP_025 | D1: English Translation | E1: English Translation | H1: English Translation | I1: English Translation
A2: memo | B2: ID | C2: Step | D2: Verification items | E2: detail | F2: 전압 | G2: 전원 | H2: Execution Procedure | I2: Expected value | J2: 결과 | K2: 측정값 | L2: 비고 | N2: 매뉴얼 기본 | O2: 자동화 기본 | P2: 자동화 반영 | Q2: 사양구분 | R2: 과거차문제
A3: [BLTN_CAM-Function-005] Continuous Parking Recording
A4: - Check initial recording settings - Check recording status signal - Check camera/switch indicator | B4: OWP_001 | C4: 1 | D4: [Continuous recording while parked] | E4: Check initial values ​​for continuous parking recording settings | F4: 12 V | G4: IGN | H4: ▪ ICUPowerAutoCutMode = 0x0(Factory mode) → 0x2(Customer mode) ▪ Built-in Cam Main Screen ▪ [ccNC Settings] - [General] - [Reset] - [Delete Guest Profile / Reset System] - Check Default Values | I4: ▪ Check Initial Values - Domestic/Japan/North America/Europe: Always Parking OFF, Parking Event OFF, Event Notification ON - Russia/Middle East: Always Parking OFF, Parking Event OFF, Event Notification OFF : Initial values ​​after changing from Factory mode to Customer mode | J4: Pass | P4: O | Q4: 주차녹화_지원
C5: 2 | H5: ▪ Turn on Driving Continuous Recording (to check the initial value after FRS setting operation) ▪ [ccNC Settings] - [General] - [Reset] - Proceed with Guest Profile or Full Reset | I5: ▪ Domestic/Japan/North America BLTN_CAM_RecSet_OWP = 0x2(ON) : The default recording setting is ON upon initialization after FRS setup operation ▪ Europe/Russia/Middle East BLTN_CAM_RecSet_OWP = 0x00(Default) : The default recording setting is Default upon initialization after FRS setup operation ※ Parking recording applied as an exception for JG1 RUS | J5: Pass | P5: O | Q5: 주차녹화_지원
C6: 3 | H6: ▪ [Settings] - [Event Detection Sensitivity] - Check Recording While Parked | I6: ▪ BLTN_CAM_SenSet_PEV = 0x3(Lv.3) | J6: Pass | P6: O | Q6: 주차녹화_지원
C7: 4 | E7: Parking Continuous Recording Time Setting (~20Hr Specification) - Check Initial Value | F7: 12 V | G7: IGN | H7: ▪ [Recording while parked] - [Recording time while parked] - Check initial value | I7: ▪ BLTN_CAM_Set_PrkTime = 0xC(20Hr) 0x1 ~ 0x14 (1Hr~20Hr) | J7: Pass | N7: O | P7: O | Q7: 주차녹화_지원
C8: 5 | E8: Confirmation of continuous parking recording operation | F8: 12 V | G8: B+ | H8: ▪ ACC, IGN OFF ▪ Check recording status signal | I8: ▪ BLTN_CAM_RecSta_OWP = 0x1(Recording) : The difference between the actual recording start time (check recording file) and the signal ON must be within 2 seconds. ▪ BLTN_CAM_RecSta_OWD = 0x0(OFF) ▪ No recording start delay (recording starts within 5 seconds based on GN7) | J8: Pass | N8: O | O8: O | P8: O | Q8: 주차녹화_지원
C9: 6 | H9: ▪ Check front/rear camera indicator | I9: ▪ F/R-CAM_INDI = Blink - Blink Frequency: 0.5Hz(Duty : 50%) | N9: O | O9: X | P9: X | Q9: 주차녹화_지원
C10: 7 | H10: ▪ Check EVENT_SW_INDI | I10: ▪ EVENT_SW_INDI = ON | J10: Pass | N10: O | O10: O | P10: O | Q10: 주차녹화_지원
A11: [Continuous Recording While Parked] - 2 - Verify Recording Settings OFF - Verify Recording File Creation - Check IGN/ACC Power Impact | B11: OWP_002 | C11: 1 | D11: [Continuous Recording While Parked] Setting ON/OFF | E11: Check that the continuous parking recording setting is OFF. | F11: 12 V | G11: IGN | H11: ▪ Switch to Built-in Camera View ▪ [Settings] - [Recording] - [Recording While Parked] - Turn Off Continuous Recording | I11: ▪ BLTN_CAM_RecSet_OWP = 0x1(OFF) | J11: Pass | N11: O | O11: O | P11: O | Q11: 주차녹화_지원
C12: 2 | E12: Confirmation that continuous parking recording does not operate when recording setting is OFF : Domestic/Japan/North America | F12: 12 V | G12: B+ | H12: ▪ Check recording status signal | I12: ▪ BLTN_CAM_RecSta_OWP = 0x0(OFF) | J12: Pass | N12: O | O12: O | P12: O | Q12: 주차녹화_지원
C13: 3 | H13: ▪ Check front/rear camera indicator | I13: ▪ F/R-CAM_INDI = OFF | N13: O | O13: X | P13: X | Q13: 주차녹화_지원
C14: 4 | H14: ▪ Check EVENT_SW_INDI | I14: ▪ EVENT_SW_INDI = OFF | J14: Pass | N14: O | O14: O | P14: O | Q14: 주차녹화_지원
C15: 5 | E15: Confirmed that continuous parking recording is not working for Europe/Russia/Middle East markets. ※ Parking recording applied as an exception for JG1 RUS. | F15: 12 V | G15: IGN | H15: ▪ Switch to Built-in Camera View ▪ [Settings] - [Recording] - [Recording While Parked] - Turn On Continuous Recording | I15: ▪ BLTN_CAM_RecSet_OWP = 0x0(Defualt) | N15: O | O15: O | P15: O | Q15: 주차녹화_미지원
C16: 6 | E16: Check BLTN_CAM_Prk_Oprable_Time | F16: 12V | G16: B+ | H16: ▪ SOC Abnormal Status - P-LBM SoC: 0xFF - eAGM SoC: No reception or Invalid (0x65~0xFE) or Error (0xFF) transmission ▪ [Settings] - [Recording] - [Recording While Parked] - Continuous Recording ON ▪ ACC & IGN OFF | I16: ▪ BLTN_CAM_Prk_Oprable_Time = 0x00 | J16: Pass | P16: O | Q16: 주차녹화_지원
C17: 7 | E17: Confirm recording file creation (3 minutes) - Create 1 3-minute recording file | F17: 12 V | G17: IGN | H17: ▪ Built-in Cam Main Screen ▪ [Settings] - [Recording] - [Recording While Parked] - Continuous Recording ON ▪ ACC & IGN OFF ▪ Wait 3 minutes, then ACC & IGN ON ▪ Return to Built-in Cam Main Screen and check the [Continuous Recording While Parked] library | I17: ▪ Verify that continuous recording files are saved while parked - Verify that a single list containing Front + Rear + Side video (3 min) is created ▪ There should be no issues with video distortion, black screens, noise, or color quality - The progress bar plays to the end during playback | L17: 과거차문제 PASTI-340 주차녹화 진입 초기에 후방영상 블랙으로 저장 되며 간헐적으로 썸네일도 블랙 저장 | N17: O | P17: X | Q17: 주차녹화_지원 | R17: O
C18: 8 | E18: [Conditions of Evil] ACC&IGN Quickly turn ON/OFF 20 times, then OFF | F18: 12 V | G18: IGN | H18: ▪ Quickly turn ACC&IGN ON/OFF 20 times, then OFF (Quickly press the actual vehicle engine start button) | I18: ▪ Start parking recording successfully ▪ Check if there are any unplayable recording files (check thumbnails as well) | J18: Pass | N18: O | P18: O | Q18: 주차녹화_지원 | R18: O
C19: 9 | E19: [Evil Conditions] Parking Recording Setting Off Repeat ACC&IGN quickly ON/OFF 20 times, then OFF | F19: 12 V | G19: IGN | H19: ▪ Auxiliary battery connected, Parking recording set Off ▪ Quickly turn ACC&IGN ON/OFF 20 times, then turn OFF (Quickly press the actual vehicle's engine start button) | I19: ▪ Do not enter parking recording ▪ Must satisfy quiescent current specifications | J19: Pass | P19: O | Q19: 주차녹화_지원 | R19: O
A20: [Continuous Recording While Parked] : Full-time Recording ※ Check the auxiliary battery tab for features related to parking recording time. | B20: OWP_003 | C20: 1 | D20: [Continuous Recording While Parked] : Full-time Recording | E20: Confirmation of recording file creation (20 hours) | F20: 12 V | G20: IGN | H20: ▪ Turn OFF ACC & IGN after setting to 20-hour continuous parking recording ▪ After turning the KEY ON, enter the built-in cam screen and check the continuous parking recording box | I20: ▪ Confirmation of continuous recording file saving while parked - Confirmation of creation of a list of 40 Front, Rear, and Side videos (30 minutes) | P20: X | Q20: 주차녹화_지원 | R20: O
C21: 2 | E21: Check for interruptions in related actions during continuous recording | F21: 12 V | G21: B+ | H21: ▪ Maintain CAN Alive status by inputting an NM signal during 20-hour continuous parking recording. ▪ Check the BLTN_CAM_RecSta_OWP signal in the CAN LOG after parking recording is complete. | I21: ▪ The BLTN_CAM_RecSta_OWP signal will not be turned OFF at the time of individual file saving. | P21: X | Q21: 주차녹화_지원 | R21: O
C22: 3 | E22: Confirmation of recording file creation (12 hours) | F22: 12 V | G22: IGN | H22: ▪ Turn OFF ACC & IGN after setting to 12-hour continuous parking recording ▪ After turning the KEY ON, enter the built-in cam screen and check the continuous parking storage box | I22: ▪ Confirmation of continuous recording file saving while parked - Confirmation of creation of a list of 24 Front, Rear, and Side videos (30 minutes) | P22: X | Q22: 주차녹화_지원 | R22: O
C23: 4 | E23: Confirmation of recording file creation (6 hours) | F23: 12 V | G23: IGN | H23: ▪ Turn OFF ACC & IGN after setting to 6-hour continuous parking recording ▪ After turning the KEY ON, enter the built-in cam screen and check the continuous parking recording box | I23: ▪ Confirmation of continuous recording file saving while parked - Confirmation of creation of a list of 12 Front, Rear, and Side videos (30 minutes) | P23: X | Q23: 주차녹화_지원 | R23: O
C24: 5 | E24: Confirmation of recording file creation (2 hours) | F24: 12 V | G24: IGN | H24: ▪ Turn OFF ACC & IGN after setting continuous parking recording for 2 hours ▪ After turning the KEY ON, enter the built-in cam screen and check the continuous parking recording box | I24: ▪ Confirmation of continuous recording file saving while parked - Confirmation of creation of 4 lists for Front, Rear, and Side videos (30 minutes) | P24: X | Q24: 주차녹화_지원 | R24: O
C25: 6 | E25: Separate group index when date changes during recording | F25: 12 V | G25: B+ | H25: ▪ Parking recording starts at 23:40 ▪ Check the parking recording video list after 3 recording files are created 1 hour later | I25: ▪ Created as 2 recording groups - 23:40:00 ~ 00:10:00 - 00:10:00 ~ 00:40:00 | P25: X | Q25: 주차녹화_지원 | R25: O
C26: 7 | E26: Check recording file specifications | F26: 12 V | G26: IGN | H26: ▪ Check the generated recording file on the PC | I26: ▪ Video saving/playback frame rate 2 FPS | N26: O | P26: X | Q26: 주차녹화_지원 | R26: O
C27: 8 | I27: ▪ 3rd Generation: 3840 * 2160 (Front/Rear Camera) 1280 * 1440 (Side Camera) (3M) | N27: O | P27: X | Q27: 주차녹화_지원 | R27: O
C28: 9 | I28: ▪ No horizontal flip of the video | N28: O | P28: X | Q28: 주차녹화_지원 | R28: O
A29: [Continuous Recording While Parked] : Simultaneous occurrence of Parking Continuous / Switch Event / Impact Event | B29: OWP_004 | C29: 1 | D29: [Continuous Recording While Parked] : Checking the Impact of Simultaneous Recording | E29: Verification of impact when recording other videos simultaneously during parking recording - Operation verification | F29: 12 V | G29: IGN | H29: ▪ Proceed with the following while parking recording is in progress after turning off the key ▪ Enable Switch Event ▪ Enable Impact Event (Event Recording Setting ON) ▪ Wait 1 minute ▪ Built-in Cam Main Screen | I29: ▪ BLTN_CAM_RecSet_OWP = 0x2(ON) ▪ F/R-CAM_INDI No issues ▪ EVENT_SW_INDI No issues | J29: Pass | P29: O | Q29: 주차녹화_지원
C30: 2 | E30: Checking the impact of simultaneous recording of other videos during parking recording - Video verification | F30: 12 V | G30: IGN | H30: ▪ [Always check while parked] Check locker | I30: ▪ Confirmation of continuous recording file saving while parked - Confirmation of creation of Front, Rear, & Side video (60 sec) list | P30: X | Q30: 주차녹화_지원
A31: [When camera video is not input] | B31: OWP_005 | C31: 1 | D31: [When camera video is not input] | E31: Front camera removal, parking recording + manual/impact events | F31: 12 V | G31: B+ | H31: ▪ Start parking recording ▪ Remove front camera after 30 seconds ▪ Reinstall camera after 20 seconds ▪ Manual, trigger impact event ▪ Check generated recording file after 30 seconds | I31: ▪ Recorded video file created (Black screen recorded if no video input) ▪ Camera restored to normal after installation | P31: X | Q31: 주차녹화_지원
C32: 2 | E32: Rearview camera removal, parking recording + manual/impact events | F32: 12 V | G32: B+ | H32: ▪ Start continuous parking recording ▪ Remove rear camera after waiting 30 seconds ▪ Reinstall camera after waiting 20 seconds ▪ Mandate impact event ▪ Check generated recording file after waiting 30 seconds | I32: ▪ Continuous recording, impact video file generated (black screen recording if no video input) ▪ Camera returns to normal after installation | P32: X | Q32: 주차녹화_지원
C33: 3 | E33: Left rear camera removed, parking recording + manual/impact events | F33: 12 V | G33: B+ | H33: ▪ Start continuous parking recording ▪ Remove left rear camera after 30 seconds ▪ Reinstall camera after 20 seconds ▪ Manual, enable impact event ▪ Check generated recording file after 30 seconds | I33: ▪ Continuous recording, impact video file generated (black screen recording if no video input) ▪ Camera returns to normal after installation
C34: 4 | E34: Right-side camera removed, parking recording + manual/impact events | F34: 12 V | G34: B+ | H34: ▪ Start continuous parking recording ▪ Remove right-side camera after 30 seconds ▪ Reinstall camera after 20 seconds ▪ Manual, enable impact event ▪ Check generated recording file after 30 seconds | I34: ▪ Continuous recording, impact video file generated (black screen recording if no video input) ▪ Camera returns to normal after installation
C35: 5 | E35: Front/Rear/Left/Right Side Camera Removal, Always Parking + Manual/Impact Events | F35: 12 V | G35: B+ | H35: ▪ Start parking recording ▪ Wait 30 seconds, then remove front, rear, left side, and right side cameras ▪ Wait 20 seconds, then reattach the cameras ▪ Manual, enable impact event ▪ Wait 30 seconds, then check the generated recording file | I35: ▪ Recorded video file created (Black screen recorded if no video input) ▪ Camera restored to normal after installation | P35: X | Q35: 주차녹화_지원
C36: 6 | E36: When attaching/detaching the front camera during parking recording | F36: 12 V | G36: IGN | H36: ▪ Removal/Installation of front camera during parking recording | I36: ▪ Recorded video file created (Black screen recorded if no video input) ▪ Camera restored to normal after installation (Recorded video plays normally) ▪ Impact event recording did not occur | P36: X | Q36: 주차녹화_지원
C37: 7 | E37: Impact of Front Camera Removal During Parking Recording on CAN Communication | F37: 12 V | G37: IGN | H37: ▪ Removal/Installation of front camera during parking recording | I37: ▪ Maintain normal CAN communication | P37: X | Q37: 주차녹화_지원
C38: 8 | E38: When attaching or detaching the rear camera during parking recording | F38: 12 V | G38: B+ | H38: ▪ Parking Recording in Progress (Network Sleep) ▪ Rear Camera Detachment ▪ KEY ON | I38: ▪ Recorded video file created (Black screen recorded if no video input) ▪ Camera restored to normal after installation (Recorded video plays normally) ▪ Impact event recording did not occur | P38: X | Q38: 주차녹화_지원
C39: 9 | E39: When attaching or detaching the left rear camera during parking recording | F39: 12 V | G39: B+ | H39: ▪ Parking Recording in Progress (Network Sleep) ▪ Left Side Camera Detachment ▪ KEY ON | I39: ▪ Recorded video file created (Black screen recorded if no video input) ▪ Camera restored to normal after installation (Recorded video plays normally) ▪ Impact event recording did not occur
C40: 10 | E40: When attaching or detaching the right-side camera during parking recording | F40: 12 V | G40: B+ | H40: ▪ Parking Recording in Progress (Network Sleep) ▪ Right Side Camera Detachment ▪ KEY ON | I40: ▪ Recorded video file created (Black screen recorded if no video input) ▪ Camera restored to normal after installation (Recorded video plays normally) ▪ Impact event recording did not occur
...

Sheet HU 연동기능
A1: English Translation | B1: {="HU_"&TEXT(MAX(IFERROR(--MID($B$2:$B$5003,5,3),0)),"000")} -> HU_049 | D1: English Translation | E1: English Translation | H1: English Translation | I1: English Translation
A2: memo | B2: ID | C2: Step | D2: Verification items | E2: detail | F2: 전압 | G2: 전원 | H2: Execution Procedure | I2: Expected value | J2: 결과 | K2: 측정값 | L2: 비고 | N2: 매뉴얼 기본 | O2: 자동화 기본 | P2: 자동화 반영 | Q2: 사양구분 | R2: 과거차문제
A3: [BLTN_CAM-Function-008] System Settings
A4: [Built-in Cam Screen Mode] (1) : HU UI mode/ Built-In Cam mode | B4: HU_001 | C4: 1 | D4: [Built-in Cam Screen Mode] (1) | E4: Built-in Cam Mode Video Output Confirmation | F4: 12V | G4: IGN | H4: ▪ AVN Mode Status ▪ Touch Built-in Cam Menu Icon (BLTN_CAM_LVDS_Mode_Cmd = 0x0:Front and Rear Camera) ▪ Touch Real-time Screen ▪ Go Back ▪ Confirm Repeat 10 times | I4: ▪ BLTN_CAM_LVDS_Mode_State = 0x0: Front and Rear Camera : LVDS video output switching time within 2 seconds (Approximately +1 second can be expected as CCNC generates the GUI) ▪ Confirmation of normal output of video list thumbnails | N4: O | P4: X
C5: 2 | E5: Check BLTN_CAM mode entry signal | F5: 12V | G5: IGN | H5: ▪ Touch the Built-In Cam screen entry button (HU_BLTN_CAM_UI_Mode = 0x1 : Built-In Cam Mode) | I5: ▪ BLTN_CAM_HU_UI_Mode (0x0: HU UI mode) → invalid → (0x2: Preparing BLTN_CAM Mode) → invalid → (0x1:BLTN_CAM mode) | J5: Pass | N5: O | P5: O
C6: 3 | E6: Transition to AVN mode by turning the KEY OFF while in BLTN_CAM mode | F6: 12V | G6: IGN | H6: ▪ Turn KEY OFF while in Built-in Cam mode -'BLTN_CAM_UI_Mode_Tmt_Req signal not transmitted confirmed | I6: ▪ BLTN_CAM_HU_UI_Mode (0x1:BLTN_CAM mode) → invalid → (0x0: HU UI mode) → invalid → (0x0: HU UI mode) | J6: Pass | N6: O | P6: O
C7: 4 | E7: AVN mode transition via AVN mode signal | F7: 12V | G7: IGN | H7: ▪ Home/Back/ccNC Physical Button Button Touch (HU_BLTN_CAM_UI_Mode = 0x0 : HU UI Mode) | I7: ▪ BLTN_CAM_HU_UI_Mode (0x1:BLTN_CAM mode) → invalid → (0x0: HU UI mode) | J7: Pass | N7: O | P7: O
C8: 5 | E8: AVN mode ↔ BLTN_CAM mode | F8: 12V | G8: IGN | H8: ▪ Touch the built-in cam screen entry button ▪ Touch the Home button (repeat quickly 10 times) | I8: ▪ When in AVN mode after repeatedly entering and exiting Built-in Cam mode: Driving recording starts normally (without delay) | N8: O | P8: X
C9: 6 | I9: ▪ In Built-in Cam Mode: Driving recording is OFF, and recorded video will play back normally. | N9: O | P9: X
C10: 7 | I10: ▪ In Built-in Cam Mode: Recorded video will play normally | N10: O | P10: X
C11: 8 | E11: Exiting BLTN_CAM mode midway | F11: 12V | G11: IGN | H11: ▪ Touch the built-in cam screen entry button ▪ Touch the CCNC Home button on the screen transition loading screen (repeat 10 times for confirmation) | I11: ▪ Start driving recording immediately when the repetitive action stops | J11: Pass | P11: O
C12: 9 | E12: Attempting to quickly enter built-in cam mode during boot-up | F12: 12V | G12: B+ | H12: ▪ ACC & IGN ON ▪ Quickly and continuously tap the Built-in Cam mode entry icon | I12: ▪ Built-in cam mode will be entered after booting is complete (enters within 2 seconds after booting is complete) | J12: Pass | P12: O
C13: 10 | I13: ▪ Driving recording will begin when the Back button is touched (1 second after exiting Built-in Cam mode) | J13: Pass | P13: O
C14: 11 | E14: Condition preventing entry into Built-in Cam mode: During booting | F14: 12V | G14: IGN | H14: ▪ Built-in Cam B+ Reset | I14: ▪ Outputs 0xD until Built-in Cam boot is complete, 0x0 after completion ▪ BLTN_CAM_HU_UI_Mode invalid → (0xD : Built-in CAM not Ready to be HU UI Mode) → invalid → (0x0: HU UI mode) | L14: 과거차문제 PASTI-357 AR Navi 뷰 녹색 화면 출력 | P14: X | R14: O
C15: 12 | H15: ▪ Enter Built-in Cam mode after Built-in Cam has finished booting | I15: ▪ BLTN_CAM_HU_UI_Mode (0x0: HU UI mode) → invalid → (0x2: Preparing BLTN_CAM Mode) → invalid → (0x1:BLTN_CAM mode) | P15: X | R15: O
C16: 13 | E16: Conditions under which Built-in Cam Mode cannot be entered (Parking Recording) : Sleep → KEY ON | F16: 12V | G16: B+ | H16: ▪ During parking recording (Network Sleep state) ▪ Inject NM signal to wake up the network | I16: ▪ BLTN_CAM_HU_UI_Mode = 0xD: Built-in CAM not Ready to be HU UI Mode | J16: Pass | P16: O | R16: O
C17: 14 | G17: IGN | H17: ▪ KEY ON | I17: ▪ Outputs 0xD until Built-in Cam boot complete, 0x0 after completion ▪ BLTN_CAM_HU_UI_Mode (0xD: Built-in CAM not Ready to be HU UI Mode) → invalid → (0x0: HU UI mode) | J17: Pass | P17: O | R17: O
C18: 15 | H18: ▪ Enter Built-in Cam Mode | I18: ▪ BLTN_CAM_HU_UI_Mode (0x0: HU UI mode) → invalid → (0x2: Preparing BLTN_CAM Mode) → invalid → (0x1:BLTN_CAM mode) | J18: Pass | P18: O | R18: O
C19: 16 | E19: Conditions under which Built-in Cam mode cannot be entered (Parking Motion Recording) : Sleep → KEY ON | F19: 12V | G19: B+ | H19: ▪ During parking motion recording (Network Sleep state) ▪ Inject NM signal to wake up the network | I19: ▪ BLTN_CAM_HU_UI_Mode = 0xD: Built-in CAM not Ready to be HU UI Mode | J19: Pass | P19: O | R19: O
C20: 17 | G20: IGN | H20: ▪ KEY ON | I20: ▪ Outputs 0xD until Built-in Cam boot complete, 0x0 after completion ▪ BLTN_CAM_HU_UI_Mode (0xD: Built-in CAM not Ready to be HU UI Mode) → invalid → (0x0: HU UI mode) | J20: Pass | P20: O | R20: O
C21: 18 | H21: ▪ Enter Built-in Cam Mode | I21: ▪ BLTN_CAM_HU_UI_Mode (0x0: HU UI mode) → invalid → (0x2: Preparing BLTN_CAM Mode) → invalid → (0x1:BLTN_CAM mode) | J21: Pass | P21: O | R21: O
C22: 19 | E22: Confirm text output when entering Built-in Cam mode | F22: 12V | G22: IGN | H22: ▪ Enter Built-in Cam Mode | I22: ▪ Print legal notice text | P22: X
A23: [Built-in Cam Screen Mode] : Performance Recording - Performance Option Performance Recording applies only to specialized vehicle specifications. (CE1 KN) | B23: HU_029 | C23: 1 | D23: [Built-in Cam Screen Mode] - Performance Recording | E23: Check Performance Options Built-in Cam Video | F23: 12V | G23: IGN | H23: ▪ Enter N Mode within AVN and tap Performance Option ▪ Tap N Race Cam in the item, then tap the "File" button to access Built-in Cam (BLTN_CAM_LVDS_Mode_Cmd = 0x0:Front and Rear Camera) ▪ Tap Real-time Screen ▪ Go Back ▪ Confirm repeat 10 times | I23: ▪ BLTN_CAM_LVDS_Mode_State = 0x0: Front and Rear Camera : LVDS video output switching time within 2 seconds (Approximately +1 second can be expected as CCNC generates the GUI) ▪ Confirmation of normal output of video list thumbnails | P23: X | Q23: 퍼포먼스_지원
C24: 2 | E24: Check BLTN_CAM mode entry signal | F24: 12V | G24: IGN | H24: ▪ Enter Built-In Cam by touching the N Race Cam file button in Performance Options (HU_BLTN_CAM_UI_Mode = 0x1 : Built-In Cam Mode) | I24: ▪ BLTN_CAM_HU_UI_Mode (0x0: HU UI mode) → invalid → (0x2: Preparing BLTN_CAM Mode) → invalid → (0x1:BLTN_CAM mode) | P24: X | Q24: 퍼포먼스_지원
C25: 3 | E25: Transition to AVN mode by turning the key off while in BLTN_CAM mode | F25: 12V | G25: IGN | H25: ▪ Turn KEY OFF while in Built-in Cam mode -'BLTN_CAM_UI_Mode_Tmt_Req signal not transmitted confirmed | I25: ▪ BLTN_CAM_HU_UI_Mode (0x1:BLTN_CAM mode) → invalid → (0x0: HU UI mode) → invalid → (0x0: HU UI mode) | P25: X | Q25: 퍼포먼스_지원
C26: 4 | E26: AVN mode transition via AVN mode signal | F26: 12V | G26: IGN | H26: ▪ Home/Back/ccNC Physical Button Button Touch (HU_BLTN_CAM_UI_Mode = 0x0 : HU UI Mode) | I26: ▪ BLTN_CAM_HU_UI_Mode (0x1:BLTN_CAM mode) → invalid → (0x0: HU UI mode) | P26: X | Q26: 퍼포먼스_지원
C27: 5 | E27: Performance Options ↔ BLTN_CAM mode | F27: 12V | G27: IGN | H27: ▪ Tap the N Race Cam file button in Performance Options to access the built-in cam. ▪ Tap the Back button (repeat quickly 10 times for confirmation). | I27: ▪ When the Performance Options screen appears after repeatedly entering and exiting Built-in Cam Mode: Driving recording starts normally (without delay) | P27: X | Q27: 퍼포먼스_지원
C28: 6 | I28: ▪ In Built-in Cam Mode: Driving recording is OFF, and recorded video will play back normally. | P28: X | Q28: 퍼포먼스_지원
C29: 7 | I29: ▪ The Performance Options screen will be displayed after touching Back. | P29: X | Q29: 퍼포먼스_지원
C30: 8 | E30: Exiting BLTN_CAM mode midway | F30: 12V | G30: IGN | H30: ▪ Touch the built-in cam screen entry button ▪ Touch the CCNC Home button on the screen transition loading screen (repeat 10 times for confirmation) | I30: ▪ Start driving recording immediately when the repetitive action stops | P30: X | Q30: 퍼포먼스_지원
C31: 9 | E31: Attempting to quickly enter built-in cam mode during boot-up | F31: 12V | G31: B+ | H31: ▪ Turn ACC & IGN ON after KEY OFF ▪ Quickly and continuously tap the Built-in Cam icon in Performance Options | I31: ▪ Built-in cam mode will be entered after booting is complete (enters within 2 seconds after booting is complete) | P31: X | Q31: 퍼포먼스_지원
C32: 10 | I32: ▪ Driving recording will begin when the Back button is touched (1 second after exiting Built-in Cam mode) | P32: X | Q32: 퍼포먼스_지원
C33: 11 | E33: Condition preventing entry into Built-in Cam mode: During booting | F33: 12V | G33: IGN | H33: ▪ Built-in Cam B+ Reset | I33: ▪ Outputs 0xD until Built-in Cam boot is complete, 0x0 after completion ▪ BLTN_CAM_HU_UI_Mode invalid → (0xD : Built-in CAM not Ready to be HU UI Mode) → invalid → (0x0: HU UI mode) | L33: 과거차문제 PASTI-357 AR Navi 뷰 녹색 화면 출력 | P33: X | Q33: 퍼포먼스_지원 | R33: O
C34: 12 | H34: ▪ After the Built-in Cam has finished booting, access the Built-in Cam from Performance Options. | I34: ▪ BLTN_CAM_HU_UI_Mode (0x0: HU UI mode) → invalid → (0x2: Preparing BLTN_CAM Mode) → invalid → (0x1:BLTN_CAM mode) | P34: X | Q34: 퍼포먼스_지원 | R34: O
C35: 13 | E35: Confirm text output when entering Built-in Cam mode | F35: 12V | G35: IGN | H35: ▪ Enter Built-in Cam Mode | I35: ▪ Print legal notice text | P35: X | Q35: 퍼포먼스_지원
C36: 14 | E36: N Mode N Race Cam Widget Continuous Touch | F36: 12V | G36: IGN | H36: ▪ Enter N Mode by touching it in the AVN ▪ In N Race Cam, repeatedly touch the top of the widget instead of the REC button | I36: ▪ Go to N Race Cam in Performance Options | P36: X | Q36: 퍼포먼스_지원
A37: [Built-in Cam Screen Mode] (2) : Undefined value | B37: HU_002 | C37: 1 | D37: [Built-in Cam Screen Mode] (2) Undefined value | E37: HS-CAN: [HU_BLTN_CAM_PE_00_200ms] - HU_UI_Mode = Reserved B2-FD: [BLTN_CAM_FD_HU_01_200ms] - HU_UI_Mode = Reserved | F37: 12V | G37: IGN | H37: ▪ [HU_BLTN_CAM_PE_00_200ms] - HU_BLTN_CAM_UI_Mode = 0x3 (Reserved) | I37: ▪ BLTN_CAM_HU_UI_Mode maintains previous state | J37: Pass | P37: O
C38: 2 | H38: ▪ [HU_BLTN_CAM_PE_00_200ms] - HU_BLTN_CAM_UI_Mode = 0x4 (Reserved) | I38: ▪ BLTN_CAM_HU_UI_Mode maintains previous state | J38: Pass | P38: O
C39: 3 | H39: ▪ [HU_BLTN_CAM_PE_00_200ms] - HU_BLTN_CAM_UI_Mode = 0x5 (Reserved) | I39: ▪ BLTN_CAM_HU_UI_Mode maintains previous state | J39: Pass | P39: O
C40: 4 | H40: ▪ [HU_BLTN_CAM_PE_00_200ms] - HU_BLTN_CAM_UI_Mode = 0x6 (Reserved) | I40: ▪ BLTN_CAM_HU_UI_Mode maintains previous state | J40: Pass | P40: O
...

Sheet 보조배터리 연동기능
A1: English Translation | B1: {="BAT_"&TEXT(MAX(IFERROR(--MID($B$2:$B$4984,5,3),0)),"000")} -> BAT_059 | D1: English Translation | E1: English Translation | H1: English Translation | I1: English Translation
A2: memo | B2: ID | C2: Step | D2: Verification items | E2: detail | F2: 전압 | G2: 전원 | H2: Execution Procedure | I2: Expected value | J2: 결과 | K2: 측정값 | L2: 비고 | N2: 매뉴얼 기본 | O2: 자동화 기본 | P2: 자동화 반영 | Q2: 사양구분 | R2: 과거차 문제
A3: [BLTN_CAM-Function-010] Power Bank Interconnection Function
A4: [Power Bank Recognition] : Check GUI | B4: BAT_001 | C4: 1 | D4: [Power Bank Recognition]: Check GUI | E4: Disconnect/Insert Auxiliary Battery Cable - Verify access to the Parking Recording settings menu when inserting the auxiliary battery - Check the instruction page when removing the auxiliary battery - Check by AVN/Built-in Cam mode | F4: 12 V | G4: IGN | H4: ▪ Connect auxiliary battery cable ▪ Check parking recording settings and available recording time on the built-in cam main screen ▪ Check the recording ON/OFF setting menu in the recording settings ▪ Check the continuous parking recording time menu in the recording time settings ▪ Check the parking event sensitivity menu in the event detection sensitivity settings | I4: ▪ Activate Parking Recording Settings Menu | N4: O | P4: X | Q4: 주차녹화 전원_보조배터리
C5: 2 | F5: 12 V | G5: IGN | H5: ▪ Auxiliary battery removed ▪ Check parking recording settings and available recording time on the built-in cam main screen ▪ Check the recording ON/OFF setting menu in the recording settings ▪ Check the continuous parking recording time menu in the recording time settings ▪ Check the parking event sensitivity menu in the event detection sensitivity settings | I5: ▪ Disable Parking Recording Settings Menu ※ 2.5th Generation Vehicles Keep Parking Recording Settings Menu Enabled | P5: X | Q5: 주차녹화 전원_보조배터리
C6: 3 | F6: 12 V | G6: IGN | H6: ▪ Auxiliary battery removed ▪ Built-in Cam Settings - Enter Menu ▪ Connect Auxiliary battery | I6: ▪ Activate Parking Recording Settings Menu | P6: X | Q6: 주차녹화 전원_보조배터리
C7: 4 | F7: 12 V | G7: IGN | H7: ▪ Switch AVN modes ▪ Disconnect and reconnect the auxiliary battery cable ▪ Enter Built-in Cam mode and access the Park Recording menu | I7: ▪ Activate Parking Recording Settings Menu | P7: X | Q7: 주차녹화 전원_보조배터리
C8: 5 | E8: Parking recording time setting | F8: 12 V | G8: IGN | H8: ▪ Built-in Cam Mode - Settings Menu - Record While Parked ▪ Quickly change settings from 2 to 20 hours | I8: ▪ No operational issues when changing settings quickly | N8: O | P8: X | Q8: 주차녹화 전원_보조배터리
A9: [Power Bank Recognition] : Check Signal | B9: BAT_002 | C9: 1 | D9: [Power Bank Recognition] : Check Signal | E9: Remove/Insert auxiliary battery cable - Check signal | F9: 12 V | G9: IGN | H9: ▪ Auxiliary battery installed (P-LBM specification) or eAGM specification ▪ Check BLTN_CAM_AuxBat_Conn_State signal | I9: ▪ BLTN_CAM_AuxBat_Conn_State = 0x1: Park Mode Operation Available (Aux. Bat. is connected (P-LBM or B-LBM) or Low Voltage battery Use.) - Installed in a vehicle capable of installing an auxiliary battery - When using both P-LBM and eAGM simultaneously for parking recording, 0x1 is transmitted because parking recording can operate even if the P-LBM is not properly connected. - eAGM Specification / eAGM + PLBM Specification / PLBM Specification | N9: O | P9: O | Q9: 주차녹화 전원_보조배터리
C10: 2 | F10: 12 V | G10: IGN | H10: ▪ Auxiliary battery not installed ▪ Check BLTN_CAM_AuxBat_Conn_State signal | I10: ▪ BLTN_CAM_AuxBat_Conn_State = 0x2: Auxiliary Battery is not connected. - Auxiliary Battery applicable on this vehicle model - Vehicle model capable of installing an auxiliary battery, but currently not installed | P10: O | Q10: 주차녹화 전원_보조배터리
C11: 3 | F11: 12 V | G11: IGN | H11: ▪ Vehicle models not supporting parking recording ▪ Auxiliary battery not installed ▪ Check BLTN_CAM_AuxBat_Conn_State signal | I11: ▪ BLTN_CAM_AuxBat_Conn_State = 0x3: Auxiliary Battery is not connected. – Auxiliary Battery not applicable on this vehicle model - Not installed on vehicle models where auxiliary battery cannot be installed | P11: O | Q11: 주차녹화_미지원
A12: [Auxiliary Battery Power Switching Conditions] | B12: BAT_003 | C12: 1 | D12: [Auxiliary Battery Power Switching Conditions] | E12: Driving (ACC) | F12: 12 V | G12: ACC | H12: ▪ Check power supplied to the built-in cam (measure current) : B+(pin. 1), Sub Bat Power(pin. 11) | I12: ▪ Power supplied to the built-in cam : Vehicle power, B+(pin. 1) | N12: O | P12: X | Q12: 주차녹화 전원_보조배터리
C13: 2 | E13: Driving (IGN) | F13: 12 V | G13: IGN | H13: ▪ Check power supplied to the built-in cam (measure current) : B+(pin. 1), Sub Bat Power(pin. 11) | I13: ▪ Power supplied to the built-in cam : Vehicle power, B+(pin. 1) | N13: O | P13: X | Q13: 주차녹화 전원_보조배터리
C14: 3 | E14: Parking (before network sleep) | F14: 12 V | G14: B+ | H14: ▪ Network Alive Status ▪ Check Power Supply to Built-in Cam (Current Measurement) : B+(pin. 1), Sub Bat Power(pin. 11) | I14: ▪ Power supplied to the built-in cam : Vehicle power, B+(pin. 1) | N14: O | P14: X | Q14: 주차녹화 전원_보조배터리
C15: 4 | E15: Parking (after network sleep) | F15: 12 V | G15: B+ | H15: ▪ Network Sleep State ▪ Check power supplied to built-in cam (current measurement) : B+(pin. 1), Sub Bat Power(pin. 11) | I15: ▪ Power supplied to the built-in cam : Auxiliary battery power, Sub Bat Power (pin. 11) | N15: O | P15: X | Q15: 주차녹화 전원_보조배터리
C16: 5 | E16: Parking (when waking up from network sleep state) | F16: 12 V | G16: B+ | H16: ▪ Check power supplied to the built-in cam (measure current) : B+ (pin. 1), Sub Bat Power (pin. 11) ▪ Network Alive state → Sleep state → Alive state | I16: ▪ Power supplied to the built-in cam : Auxiliary battery power → Vehicle power, B+ → Auxiliary battery power (during network sleep) | N16: O | P16: X | Q16: 주차녹화 전원_보조배터리
A17: [Current Consumption During Recording] <Power Switching Conditions> - Before Sleep: Built-in Cam B+ Terminal (Pin #18 based on 18-pin connector DN8) - After Sleep: Auxiliary Battery (Pin #1 of 4-pin auxiliary battery connector) | B17: BAT_004 | C17: 1 | D17: [Current Consumption During Recording] | E17: Auxiliary battery output current during driving recording | F17: 12 V | G17: IGN | H17: ▪ Measurement of auxiliary battery output current during continuous driving recording ※ Measured with auxiliary battery charged to 80% or higher | I17: ▪ Power bank current consumption 0mA | N17: O | P17: O | Q17: 주차녹화 전원_보조배터리
C18: 2 | E18: CAN Wake up (e.g., when a customer operates the remote control while parked) | F18: 12 V | G18: IGN ↓ B+ | H18: ▪ Parking Recording in Progress ▪ Waiting to Enter Sleep ▪ Random CAN Signal Input (Wake Up) ▪ Built-in Cam B+ Input Current Measurement ▪ Waiting to Sleep ▪ Built-in Cam B+ Terminal Input Power Current Measurement | I18: ▪ B+ Current consumption 2mA or less (using auxiliary battery power) | N18: O | P18: O | Q18: 주차녹화 전원_보조배터리
A19: [Event recording while using power bank] | B19: BAT_005 | C19: 1 | D19: [Event recording while using power bank] | E19: Recording impact events while using power bank - Maintaining power usage of power bank | F19: 12 V | G19: IGN ↓ B+ | H19: ▪ Parking Recording in Progress ▪ Parking Event Notification Off ▪ Enter Sleep ▪ Impact Event Authorization | I19: ▪ Maintain power from auxiliary battery ▪ FCAM_IND_Frequency = 1 ▪ EVENT_SW_Frequency = 1 | P19: O | Q19: 주차녹화 전원_보조배터리
C20: 2 | E20: Manual Event Recording While Using Power Bank - Maintain Power Bank Power | F20: 12 V | G20: IGN ↓ B+ | H20: ▪ Parking recording in progress ▪ Entering Sleep ▪ Manual event authorization | I20: ▪ Maintain power from auxiliary battery ▪ FCAM_IND_Frequency = 1 ▪ EVENT_SW_Frequency = 1 | P20: O | Q20: 주차녹화 전원_보조배터리
A21: [Removing/Reinserting Battery During Recording] ※ Implementation: Auxiliary battery reconnection standby time approx. 10 seconds (Built-in cam B+ terminal used for 10 seconds) ↑ Not a defined specification, but implemented according to the above conditions | B21: BAT_006 | C21: 1 | D21: [Removing/Reinserting Battery During Recording] | E21: Alive status Built-in Cam B+ Power Input Cut Off | F21: 12 V | G21: IGN ↓ B+ | H21: ▪ Check parking recording status | I21: ▪ FCAM_IND_Frequency = 0.5 ▪ FCAM_IND_Duty = 0.5 ▪ EVENT_SW_IND = Turned On at approximately 10V | P21: O | Q21: 주차녹화 전원_보조배터리
C22: 2 | H22: ▪ Confirm parking recording ends after disconnecting the Built-in Cam B+ power input | I22: ▪ FCAM_IND_Frequency = 0 ▪ EVENT_SW_IND = 0 | P22: O | Q22: 주차녹화 전원_보조배터리
C23: 3 | E23: Remove auxiliary battery in Alive state | F23: 12 V | G23: IGN ↓ B+ | H23: ▪ Parking recording in progress ▪ Auxiliary battery removed | I23: ▪ Parking recording continues in Alive state - Ends when entering Sleep mode | P23: O | Q23: 주차녹화 전원_보조배터리
C24: 4 | E24: Cut off power input to Built-in Cam B+ after Sleep | F24: 12 V | G24: IGN ↓ B+ | H24: ▪ Parking recording in progress ▪ Standby until Sleep ▪ Built-in cam B+ power input cut off | I24: ▪ Auxiliary battery power maintained ▪ Parking recording to be maintained, recording file normal | P24: O | Q24: 주차녹화 전원_보조배터리
C25: 5 | E25: Remove auxiliary battery after sleep | F25: 12 V | G25: IGN ↓ B+ | H25: ▪ Parking recording in progress ▪ Standby until Sleep ▪ Remove auxiliary battery ▪ Check operation after 20 seconds | I25: ▪ Use the built-in cam B+ terminal immediately after removal. ▪ Turn off the built-in cam after approximately 10 seconds. ※ There are no fixed specifications; this is based on DN8 operation. | P25: O | Q25: 주차녹화 전원_보조배터리
C26: 6 | E26: Immediately after an impact event occurs during parking recording, disconnect the auxiliary battery for 3 seconds and then reconnect it. | F26: 12 V | G26: B+ | H26: Immediately after an impact event occurs during parking recording, disconnect the auxiliary battery for 3 seconds and then reconnect it. | I26: ▪ Recorded video will be saved normally, and the recording status will not terminate abnormally | P26: O | Q26: 주차녹화 전원_보조배터리
A27: [BMS_OPERATION_CONTROL] :BAT_Charge_Control | B27: BAT_007 | C27: 1 | D27: [Charge] BMS_OPERATION_CONTROL | E27: BAT_Charge_Control = 1: Start charging (ICE) | F27: 12 V | G27: IGN | H27: ▪ IGN ON state ▪ SMK_TrmnlCtrlGrpStaBDC) signal = Running(0x4) or ▪ SMK_TrmnlCtrlGrpStaBDCEV) signal = Ready(0x3) (from ME) | I27: ▪ [LIN] BMS_OPERATION_CONTROL - Send BAT_Charge_Control = 0x1 (Start charging) once | N27: O | O27: O | P27: O | Q27: 주차녹화 전원_보조배터리
C28: 2 | E28: SMK_TrmnlCtrlGrpStaBDC = 1 :ACC | F28: 12 V | G28: B+ | H28: ▪ SMK_TrmnlCtrlGrpStaBDC = 1 :ACC | I28: ▪ Driving Recording in Progress - F/R-CAM_INDI = Flashing (Flashing Frequency: 0.5Hz) - EVENT_SW_INDI = ON - BLTN_CAM_RecSta_OWD = 0x1(Recoreding) | O28: O | P28: O | Q28: 주차녹화 전원_보조배터리
C29: 3 | E29: SMK_TrmnlCtrlGrpStaBDC = 2 :IGN | F29: 12 V | G29: B+ | H29: ▪ SMK_TrmnlCtrlGrpStaBDC = 2 :IGN | I29: ▪ Driving recording in progress | O29: O | P29: O | Q29: 주차녹화 전원_보조배터리
C30: 4 | E30: SMK_TrmnlCtrlGrpStaBDC = 3 :Cranking | F30: 12 V | G30: B+ | H30: ▪ SMK_TrmnlCtrlGrpStaBDC = 3 :Cranking | I30: ▪ Driving recording in progress | O30: O | P30: O | Q30: 주차녹화 전원_보조배터리
C31: 5 | E31: SMK_TrmnlCtrlGrpStaBDC = 4 :Engine Running | F31: 12 V | G31: B+ | H31: ▪ SMK_TrmnlCtrlGrpStaBDC = 4 :Engine Running | I31: ▪ Driving recording in progress | O31: O | P31: O | Q31: 주차녹화 전원_보조배터리
C32: 6 | E32: SMK_TrmnlCtrlGrpStaBDCEV = 1: Power ON | F32: 12 V | G32: B+ | H32: SMK_TrmnlCtrlGrpStaBDCEV = 1: Power ON | I32: ▪ Driving Recording in Progress - F/R-CAM_INDI = Flashing (Flashing Frequency: 0.5Hz) - EVENT_SW_INDI = ON - BLTN_CAM_RecSta_OWD = 0x1(Recoreding) | O32: O | P32: O | Q32: 주차녹화 전원_보조배터리
C33: 7 | E33: SMK_TrmnlCtrlGrpStaBDCEV = 2 :Cranking | F33: 12 V | G33: B+ | H33: ▪ SMK_TrmnlCtrlGrpStaBDCEV = 2 :Cranking | I33: ▪ Driving recording in progress | O33: O | P33: O | Q33: 주차녹화 전원_보조배터리
C34: 8 | E34: SMK_TrmnlCtrlGrpStaBDCEV = 3 :Ready | F34: 12 V | G34: B+ | H34: ▪ SMK_TrmnlCtrlGrpStaBDCEV = 3 :Ready | I34: ▪ Driving recording in progress | O34: O | P34: O | Q34: 주차녹화 전원_보조배터리
C35: 9 | E35: BAT_Charge_Control = 0: Stop charging/discharging (Stop charging) | F35: 12 V | G35: IGN | H35: ▪ IGN ON State ▪ Engine Status (SMK_TrmnlCtrlGrpStaBDC) Signal = Running(0x4) → 0x0(Off) or ▪ SMK_TrmnlCtrlGrpStaBDCEV) Signal = Ready(0x3) → 0x0(Off) | I35: ▪ [LIN] BMS_OPERATION_CONTROL - Send BAT_Charge_Control = 0x0 (Stop charging/discharging) once | N35: O | O35: O | P35: O | Q35: 주차녹화 전원_보조배터리
C36: 10 | E36: BAT_Charge_Control = 2: Start discharging | F36: 12 V | G36: IGN | H36: ▪ ACC & IGN OFF ▪ Enter Sleep during Parking Recording | I36: ▪ [LIN] BMS_OPERATION_CONTROL - Send BAT_Charge_Control = 0x2 (Start Discharging) once ▪ Switch to auxiliary battery power | N36: O | O36: O | P36: O | Q36: 주차녹화 전원_보조배터리
C37: 11 | E37: BAT_Charge_Control = 0: Stop charging/discharging (stop discharging) | F37: 12 V | G37: B+ | H37: ▪ ACC & IGN ON | I37: ▪ [LIN] BMS_OPERATION_CONTROL - Send BAT_Charge_Control = 0x0 (Stop charging/discharging) once ▪ Switch to auxiliary battery power | N37: O | O37: O | P37: O | Q37: 주차녹화 전원_보조배터리
A38: [BMS_OPERATION_CONTROL] :BAT_Discharging_Time | C38: 12 | E38: BAT_Discharge_Time = 0 ~ 254 (Battery discharge time setting) | F38: 12 V | G38: IGN | H38: ▪ Comparison of Set Recording Time and Battery Discharge Time ※ You must compare the two signals by turning the KEY OFF while the auxiliary battery is charging to update the Operable Time. | I38: ▪ Matches the set recording time Ex) Even if Operable Time becomes -1 when entering Sleep, this signal must transmit the actual recording time. (Not the same as the Operable Time signal) | L38: 과거차문제PASTI-352 주차 녹화 조기 종료 현상 개선 | O38: O | P38: O | Q38: 주차녹화 전원_보조배터리 | R38: O
A39: [BMS_OPERATION_CONTROL] :Key_On_Off_Info | C39: 13 | E39: Key_On_Off_Info = 0 : ACC OFF | F39: 12 V | G39: IGN | H39: ▪ ACC & IGN OFF ▪ Check ACC ON/OFF information signal | I39: ▪ ACC ON/OFF information signal at discharge point Key_On_Off_Info = 0 : Transmit ACC OFF | O39: O | P39: O | Q39: 주차녹화 전원_보조배터리
C40: 14 | E40: Key_On_Off_Info = 1 : ACC ON | F40: 12 V | G40: IGN | H40: ▪ Check ACC ON/OFF information signal | I40: ▪ ACC ON/OFF information signal at discharge point Key_On_Off_Info = 1 : Transmit ACC ON | O40: O | P40: O | Q40: 주차녹화 전원_보조배터리
...

Sheet 모바일 앱 연동기능
A1: English Translation | B1: {="APP_"&TEXT(MAX(IFERROR(--MID($B$2:$B$5000,5,3),0)),"000")} -> APP_020 | D1: English Translation | E1: English Translation | H1: English Translation | I1: English Translation
A2: memo | B2: ID | C2: Step | D2: Verification items | E2: detail | F2: 전압 | G2: 전원 | H2: Execution Procedure | I2: Expected value | J2: 결과 | K2: 측정값 | L2: 비고 | N2: 매뉴얼 기본 | O2: 자동화 기본 | P2: 자동화 반영 | Q2: 사양구분 | R2: 과거차문제
A3: [BLTN_CAM-Function-011] Mobile App Integration Function Wi-Fi Connection
A4: [WiFi Initial Setup - No Password Set] | B4: APP_001 | C4: 1 | D4: [WiFi Initial Setup - No Password Set] | E4: Wi-Fi settings initial state: Check Wi-Fi connection disabled | F4: 12 V | G4: IGN | H4: ▪ ICU_PowerAutoCutModSta = factory mode → customer mode | I4: ▪ Wifi settings - Off ▪ BLTN_CAM_WiFi_State = 0x3: Off - Password is not Set | N4: O | P4: X
C5: 2 | E5: Wi-Fi Settings Initial State: Connect Specification (CS/CW) ※ Connect Specification BLTN_CAM_WiFi_State = 0x3 Signal Not Used | F5: 12 V | G5: IGN | H5: ▪ ICU_PowerAutoCutModSta = factory mode → customer mode | I5: ▪ Wifi Settings - Off ▪ BLTN_CAM_WiFi_State = 0x0: Off | N5: O | P5: X
C6: 3 | E6: Check Wi-Fi settings to be disabled (North America/Russia) | F6: 12 V | G6: IGN | H6: ▪ Wi-Fi Connection Page - Turn WiFi Settings ON | I6: ▪ Wifi Settings - Keep Off ※ Temporarily Disabled | N6: O | P6: X
C7: 4 | E7: Verify Wi-Fi connection is disabled when no Wi-Fi password is set (Domestic/Japan/Europe/Middle East) ※ Connect specifications do not support this operation | F7: 12 V | G7: IGN | H7: ▪ Wi-Fi Connection Page - Turn WiFi Settings ON | I7: ▪ Display Wi-Fi password setting popup | N7: O | P7: X
C8: 5 | F8: 12 V | G8: IGN | H8: ↓ ' ▪ Wi-Fi Password Settings Popup - No | I8: ▪ Wifi settings - Off ▪ BLTN_CAM_WiFi_State = 0x3: Off - Password is not Set | N8: O | P8: X
A9: [WiFi Connection Status Signal] | B9: APP_002 | C9: 1 | D9: [WiFi Connection Status Signal] | E9: Built-in Cam WiFi setting OFF | F9: 12 V | G9: IGN | H9: ▪ 0x0: Wi-Fi Off | I9: ▪ BLTN_CAM_WiFi_State = 0x0: Off | N9: O | P9: X
C10: 2 | E10: Built-in cam WiFi password setup complete, WiFi settings ON | F10: 12 V | G10: IGN | H10: ▪ 0x1: Wi-Fi On, Ready to connect | I10: ▪ BLTN_CAM_WiFi_State = 0x01 : On, Ready to Connect Mobile Phone | N10: O | P10: X
C11: 3 | E11: Built-in Cam WiFi Smartphone App Connection Status | F11: 12 V | G11: IGN | H11: ▪ 0x2: Wi-Fi On, Connected | I11: ▪ BLTN_CAM_WiFi_State = 0x02: On, Mobile Phone Connected | N11: O | P11: X
