Workbook
Name 입력조건: #REF!
Name 입력조건: #REF!
Name 입력조건: #REF!
Name 입력조건: #REF!
Name 입력조건: #REF!
Name 입력조건: #REF!
Name 입력조건: #REF!
Name 입력조건: #REF!
Name 입력조건: #REF!
Name 입력조건: #REF!
Name 입력조건: #REF!
Name 입력조건: #REF!
Name 입력조건: #REF!
Name 입력조건: #REF!
Name 입력조건: #REF!
Name 입력조건: #REF!
Name 입력조건: #REF!
Name 입력조건: #REF!
Name 입력조건: #REF!
Name 입력조건: #REF!
Name 입력조건: #REF!
Name 입력조건: #REF!
Name 입력조건: #REF!
Name 입력조건: #REF!
Name 판정기준: #REF!
Name 판정기준: #REF!
Name 판정기준: #REF!
Name 판정기준: #REF!
Name 판정기준: #REF!
Name 판정기준: #REF!
Name 판정기준: #REF!
Name 판정기준: #REF!
Name 판정기준: #REF!
Name 판정기준: #REF!
Name 판정기준: #REF!
Name 판정기준: #REF!
Name 판정기준: #REF!
Name 판정기준: #REF!
Name 판정기준: #REF!
Name 판정기준: #REF!
Name 판정기준: #REF!
Name 판정기준: #REF!
Name 판정기준: #REF!
Name 판정기준: #REF!
Name 판정기준: #REF!
Name 판정기준: #REF!
Name 판정기준: #REF!
Name 판정기준: #REF!
Name 항목: #REF!
Name 항목: #REF!
Name 항목: #REF!
Name 항목: #REF!
Name 항목: #REF!
Name 항목: #REF!
Name 항목: #REF!
Name 항목: #REF!
Name 항목: #REF!
Name 항목: #REF!
Name 항목: #REF!
Name 항목: #REF!

Sheet HISTORY
A1: TestCase 변경 HISTORY | L1: 품명: BLTN_CAM
L2: 제정일자 2021- -
A3: Rev | B3: 구분 | C3: 탭 | D3: TC ID | E3: 항목 | F3: 내용 | G3: 사양구분 | H3: 사유 | I3: LCR No | J3: 적용 일자 | K3: 작성자 | L3: 자동화 동기화 여부
A4: 0 | B4: 최초작성 시작 | C4: - | E4: - | F4: - | G4: - | H4: - | I4: - | J4: 2021-10-13
A5: 0.01 | B5: 추가 | C5: 녹화 외 기본기능 | E5: [개발단계 과거이슈] | F5: 간헐적으로 실시간 영상 블랙 화면 출력 재현 시퀀스 추가 | G5: Added a sequence to intermittently reproduce real-time video black screen output. | H5: 과거이슈 추가 | I5: Add past issues | J5: 44601
A6: 0.02 | E6: [SD카드 영향성 확인] | F6: SD카드 탈거 상태로 KEY OFF | G6: Turn off the key with the SD card removed
A7: 1 | B7: - | C7: - | E7: 1차 제정완료 | F7: - | G7: - | J7: 44684
A8: 1.01 | B8: 추가 | C8: 주차 중 상시 녹화 | E8: [주차 중 이벤트 녹화] (8): 주차 중 충격 횟수에 따른 HU 표시 문구 | F8: 주차 중 충격 횟수에 따른 HU 표시 문구 확인 추가 (ccNC기능) | G8: Added confirmation of HU display text based on number of impacts while parked (ccNC function) | H8: 신규작성 | I8: New creation | J8: 44685
C9: 녹화 외 기본기능 | E9: [빌트인캠 S/W버전 시그널] | F9: BLTN_CAM_SWVerMinor3 추가 및 내용 수정 | G9: Added BLTN_CAM_SWVerMinor3 and modified content | H9: 신규작성 | I9: New creation
C10: 보조배터리 연동기능 | E10: [보조배터리 인식] : 시그널 확인 | F10: BLTN_CAM_AuxBat_Conn_State 시그널 값 확인 | G10: Check BLTN_CAM_AuxBat_Conn_State signal value | H10: 신규작성 | I10: New creation
A11: 1.02 | B11: 수정 | C11: Sleep&WakeUp | E11: [EthNM 메시지 동작 확인] | F11: 이더넷 Sleep 사양 CAN 상태 참조하는 사양변경되어 전체적으로 수정 | G11: The Ethernet Sleep specification has been modified entirely due to changes in the specification referencing CAN status. | H11: 내용보완 | I11: Content supplement | J11: 44691
A12: 1.03 | B12: 수정 | C12: 주차 중 상시 녹화 | E12: [SD카드 영향성 확인] | F12: 해당 사양 변경으로 내용 수정 | G12: Content modified due to the change in specifications. | H12: 사양변경 | I12: Change of specifications | J12: 44694
B13: 추가 | C13: 녹화 외 기본기능 | E13: [ccNC와 ccNC-Lite 구분] | F13: ccNC 및 ccNC-Lite 구분 사양 내용 추가 (ccNC기능) | G13: Added specifications distinguishing ccNC and ccNC-Lite (ccNC functions) | H13: 신규작성 | I13: New creation
C14: 통신 정합성 | E14: [LHD/RHD 구분 시그널 출력여부 확인] | F14: LHD/RHD 구분 사양 내용 추가 | G14: Added LHD/RHD distinction specifications | H14: 신규작성 | I14: New creation
B15: 추가 / 수정 | C15: 보조배터리 연동기능 | E15: [LIN] BMS_INFO_01(ID:0x12) | F15: 보조배터리 정보 시그널 내용 추가 및 수정 | G15: Adding and modifying power bank information signal content | H15: 내용보완 | I15: Content supplement
E16: [LIN] BMS_INFO_02(ID:0x13)
E17: [LIN] BMS_INFO_03(ID:0x14) : BAT_Status
B18: 추가 | E18: [BMS_OPERATION_CONTROL] : BAT_Discharging_Time | F18: 보조배터리 정보 시그널 내용 추가 | G18: Added auxiliary battery information signal content | H18: 신규작성 | I18: New creation
E19: [BMS_OPERATION_CONTROL] : Key_On_Off_Info
A20: 1.04 | B20: 추가 | C20: 진단서비스 (3) 수동검증 | E20: BLTN_CAM Internal Error (B16B0-00) (Watchdog 동작여부 확인) | F20: MCU 고장 시 | G20: When the MCU fails | H20: 신규작성 | I20: New creation | J20: 44697
F21: MCU 고장 해제 | G21: MCU failure unlocking | H21: 신규작성
F22: CPU 고장 시 | G22: When the CPU fails | H22: 신규작성
F23: CPU 고장 해제 | G23: CPU failure unlocking | H23: 신규작성
F24: G-Sensor 고장 시 | G24: When the G-Sensor fails | H24: 신규작성
F25: G-Sensor 고장 해제 | G25: G-Sensor Fault Removal | H25: 신규작성
E26: [A260] Eth RDBI CAR Info : Type, Project Name | F26: CAR Type, Project Name 정보 진단 [A260] | G26: CAR Type, Project Name Information Diagnosis [A260] | H26: 신규작성 | I26: New creation
E27: Communication Control 시동조건 적용 | F27: ENG_STAT Running 상태에서 Communication Control 요청 시 부정응답 확인 | G27: Checking for negative responses when requesting Communication Control in ENG_STAT Running state | H27: 신규작성 | I27: New creation
A28: 1.05 | B28: 추가 | C28: 녹화 외 기본기능 | E28: [녹화영상 편집기능] | F28: SD메모리 초기화 | G28: Initialize SD memory | H28: 신규작성 | I28: New creation | J28: 44705
A29: 1.06 | B29: 추가 | C29: 파일재생 및 편집 | E29: [녹화파일 프레임레이트 확인] : 주행 중 상시 녹화 | F29: 주행상시 | G29: Constant driving | H29: 신규작성 | I29: New creation | J29: 44715
F30: 주행 수동이벤트 녹화 이후 | G30: After recording the manual driving event | H30: 신규작성
F31: 주행 충격이벤트 녹화 이후 | G31: After recording the driving impact event | H31: 신규작성
F32: 타임랩스 녹화 이후 | G32: After the time-lapse recording | H32: 신규작성
F33: 주차 중 상시 녹화 이후 | G33: After continuous recording while parked | H33: 신규작성
E34: [녹화파일 프레임레이트 확인] : 주차 중 상시 녹화 | F34: 주차상시 | G34: Always parking | H34: 신규작성
F35: 주차 수동이벤트 녹화 이후 | G35: After recording the manual parking event | H35: 신규작성
F36: 주차 충격이벤트 녹화 이후 | G36: After recording the parking impact event | H36: 신규작성
B37: 추가 | C37: 주행 중 상시 녹화 | E37: [타임랩스 녹화] (7) : HU 요청 | F37: HU에서 타임랩스 시작 요청 | G37: Request to start time-lapse in HU | H37: 신규작성
F38: HU에서 타임랩스 종료 요청 | G38: Request to end time-lapse in HU | H38: 신규작성
F39: HU에서시작 후 롱키로 종료 시 | G39: When ending with a long press after starting in HU | H39: 신규작성
F40: 롱키로 시작 후 HU에서 종료 시 | G40: When starting with a long key and ending at HU | H40: 신규작성
...

Sheet 표지
D1: 플랫폼 검증 보고서 기능 검증 보고서 | J1: 작 성 | L1: 검 토 | N1: 승 인
A4: 문서 번호 | C4: 빌트인캠 2.5세대_23.24.B0.10.02_플랫폼 검증 보고서 빌트인캠 2.5세대_US4 KV JAP_P2_23.24.B0.10.02_기능 검증 보고서 | H4: 검증 목적 | J4: 플랫폼 개정 사양에 대한 기능 정합성 및 동작 유효성 검증 기능 개정 사양에 대한 기능 정합성 및 동작 유효성 검증
A5: 품 명 | C5: 빌트인캠 2.5세대 | H5: 기 간 | J5: 2026.3.24 ~ 25
A6: 참조 스펙 | C6: 01_System_Spec_BLTN_CAM_v2_4(20260115).docx | H6: 담 당 | J6: 임동혁
A7: 플랫폼 Ver. | C7: 23.25.A0.11.03
A8: CAN DB Ver. | C8: 20230523_STD_DB_CAR_2021_HS_B2_v23.05.01.dbc | H8: LIN DB Ver. | J8: P-LBM_LIN_DB_A_01.ldf
B9: 차종 | C9: 이벤트 | D9: HU 타입 | E9: HU Ver. | G9: 주차 전원 | H9: H/W Ver. | J9: 진단/OTA | M9: 품번
A10: 1 | B10: JK1 PE RUS | C10: P2 | D10: ccIC | E10: JX1PE.KOR.ccNC.000.605.230831 | G10: MLBM | H10: 1.00 | J10: 1G / CCU OTA | M10: 95720-DO000
A11: 2
A15: No | B15: 항목 | G15: 총 TC 수 | H15: 실행 TC 수 | I15: 결과 | K15: 판정 | L15: 개선 검증 | M15: 비고
I16: 적합 | J16: 부적합
A17: 1 | B17: 녹화 제어 | C17: 주행 중 녹화 관련 기능 | G17: =COUNT('주행 중 녹화 기능'!G:G) -> 362 | H17: =SUM(I17:J17) -> 150 | I17: =COUNTIF('주행 중 녹화 기능'!J:J,"Pass") -> 150 | J17: =COUNTIF('주행 중 녹화 기능'!J:J,"Fail") -> 0 | K17: Fail | L17: Pass | M17: 23.25.A0.11.03 #2 개선확인
A18: 2 | C18: 주차 중 상시 녹화 관련 기능 | G18: =COUNT('주차 후 녹화 기능'!G:G) -> 312 | H18: =SUM(I18:J18) -> 120 | I18: =COUNTIF('주차 후 녹화 기능'!J:J,"Pass") -> 120 | J18: =COUNTIF('주차 후 녹화 기능'!J:J,"Fail") -> 0 | K18: Pass | L18: -
A19: 3 | B19: 연동 제어 | C19: 헤드 유닛 연동 기능 | G19: =COUNT('HU 연동기능'!G:G) -> 326 | H19: =SUM(I19:J19) -> 143 | I19: =COUNTIF('HU 연동기능'!J:J,"Pass") -> 143 | J19: =COUNTIF('HU 연동기능'!J:J,"Fail") -> 0 | K19: Pass | L19: -
A20: 4 | C20: 보조배터리 소모 전력 및 연동 기능 | G20: =COUNT('보조배터리 연동기능'!G:G) -> 520 | H20: =SUM(I20:J20) -> 53 | I20: =COUNTIF('보조배터리 연동기능'!J:J,"Pass") -> 53 | J20: =COUNTIF('보조배터리 연동기능'!J:J,"Fail") -> 0 | K20: Pass | L20: -
A21: 5 | C21: WiFi 연결 및 모바일 앱 연동 기능 | G21: =COUNT('모바일 앱 연동기능'!G:G) -> 109 | H21: =SUM(I21:J21) -> 0 | I21: =COUNTIF('모바일 앱 연동기능'!J:J,"Pass") -> 0 | J21: =COUNTIF('모바일 앱 연동기능'!J:J,"Fail") -> 0 | K21: Pass | L21: -
A22: 6 | C22: DCM 연동 기능 | G22: =COUNT('DCM 연동기능'!G:G) -> 727 | H22: =SUM(I22:J22) -> 215 | I22: =COUNTIF('DCM 연동기능'!J:J,"Pass") -> 215 | J22: =COUNTIF('DCM 연동기능'!J:J,"Fail") -> 0 | K22: Pass | L22: -
A23: 7 | B23: 서비스 제어 | C23: 빌트인캠 상태 정보 표시 관련 기능 | G23: =COUNT('표시 관련 서비스'!G:G) -> 105 | H23: =SUM(I23:J23) -> 56 | I23: =COUNTIF('표시 관련 서비스'!J:J,"Pass") -> 56 | J23: =COUNTIF('표시 관련 서비스'!J:J,"Fail") -> 0 | K23: Pass | L23: -
A24: 8 | C24: 커넥티드 관련 빌트인캠 상태 알림 관련 기능 | G24: =COUNT('커넥티드 관련 서비스'!G:G) -> 105 | H24: =SUM(I24:J24) -> 84 | I24: =COUNTIF('커넥티드 관련 서비스'!J:J,"Pass") -> 84 | J24: =COUNTIF('커넥티드 관련 서비스'!J:J,"Fail") -> 0 | K24: Pass | L24: -
A25: 9 | B25: 기타 제어 | C25: 주행 중 차량정보(메타데이터) 저장 기능 | G25: =COUNT('차량정보 저장기능'!G:G) -> 253 | H25: =SUM(I25:J25) -> 1 | I25: =COUNTIF('차량정보 저장기능'!J:J,"Pass") -> 1 | J25: =COUNTIF('차량정보 저장기능'!J:J,"Fail") -> 0 | K25: Pass | L25: -
A26: 10 | C26: 녹화 영상 및 소리 재생 및 편집 기능 | G26: =COUNT('파일 재생 및 편집'!H:H) -> 73 | H26: =SUM(I26:J26) -> 0 | I26: =COUNTIF('파일 재생 및 편집'!K:K,"Pass") -> 0 | J26: =COUNTIF('파일 재생 및 편집'!K:K,"Fail") -> 0 | K26: Pass | L26: -
A27: 11 | C27: 녹화 파일 정보 및 SD 카드 사양 확인 | G27: =COUNTIF('저장메모리 및 파일관리'!A:A,"MEM_*") -> 273 | H27: =SUM(I27:J27) -> 0 | I27: =COUNTIF('저장메모리 및 파일관리'!J:J,"Pass") -> 0 | J27: =COUNTIF('저장메모리 및 파일관리'!J:J,"Fail") -> 0 | K27: Pass | L27: -
A28: 12 | C28: 실시간 영상 출력, 차량 모드, 업데이트 외 | G28: =COUNT('저장메모리 및 파일관리'!G:G) -> 422 | H28: =SUM(I28:J28) -> 25 | I28: =COUNTIF('녹화 외 기본기능'!J:J,"Pass") -> 25 | J28: =COUNTIF('녹화 외 기본기능'!J:J,"Fail") -> 0 | K28: Pass | L28: -
A29: 13 | B29: 동작 성능 | C29: 동작 성능 | G29: =COUNT('동작 성능'!G:G) -> 370 | H29: =SUM(I29:J29) -> 192 | I29: =COUNTIF('동작 성능'!J:J,"Pass") -> 192 | J29: =COUNTIF('동작 성능'!J:J,"Fail") -> 0 | K29: Pass | L29: -
A30: 14 | C30: 전기적 성능, 네트워크 동작 사양, 통신 정합성 외 | G30: =COUNT('비기능 외'!G:G) -> 356 | H30: =SUM(I30:J30) -> 202 | I30: =COUNTIF('비기능 외'!J:J,"Pass") -> 202 | J30: =COUNTIF('비기능 외'!J:J,"Fail") -> 0 | K30: Pass | L30: -
A31: 15 | B31: 진단 서비스 | C31: 고장진단, I/O Control 및 ERT기능 | G31: =COUNT('진단서비스 (1)'!G:G) -> 412 | H31: =SUM(I31:J31) -> 209 | I31: =COUNTIF('진단서비스 (1)'!J:J,"Pass") -> 209 | J31: =COUNTIF('진단서비스 (1)'!J:J,"Fail") -> 0 | K31: Pass | L31: -
A32: 16 | C32: ECU Identification 외 | G32: =COUNT('진단서비스 (2)'!G:G) -> 902 | H32: =SUM(I32:J32) -> 878 | I32: =COUNTIF('진단서비스 (2)'!J:J,"Pass") -> 878 | J32: =COUNTIF('진단서비스 (2)'!J:J,"Fail") -> 0 | K32: Pass | L32: -
A33: 17 | C33: Session, Communication Control 외 | G33: =COUNT('진단서비스 (3)'!G:G) -> 1499 | H33: =SUM(I33:J33) -> 1499 | I33: =COUNTIF('진단서비스 (3)'!J:J,"Pass") -> 1499 | J33: =COUNTIF('진단서비스 (3)'!J:J,"Fail") -> 0 | K33: Pass | L33: -
A34: 18 | B34: Sleep & Wakeup | C34: 기능 동작 별 Sleep 진입 확인 | G34: =COUNT(Sleep!G:G) -> 1096 | H34: =SUM(I34:J34) -> 0 | I34: =COUNTIF(Sleep!J:J,"Pass") -> 0 | J34: =COUNTIF(Sleep!J:J,"Fail") -> 0 | K34: Pass | L34: -
A35: 19 | C35: 기능 동작 별 Wakeup 및 Sleep 재진입 확인 | G35: =COUNT(Wakeup!G:G) -> 714 | H35: =SUM(I35:J35) -> 0 | I35: =COUNTIF(Wakeup!J:J,"Pass") -> 0 | J35: =COUNTIF(Wakeup!J:J,"Fail") -> 0 | K35: Pass | L35: -
A36: Total | G36: =SUM(G17:G35) -> 8936 | H36: =SUM(H17:H35) -> 3827 | I36: =SUM(I17:I35) -> 3827 | J36: =SUM(J17:J35) -> 0 | K36: Pass
A37: ■ 부적합 개선 항목 1. 2. ■ 부적합 현황 1. 2. ■ 미검증 항목 1. 2. ※ 지역별 사양 1. 내수 - 2. 북미 - 3. 유럽 -
A50: =TODAY() -> 46227

Sheet 정리
D6: 항목 | E6: STEP | F6: 자동화중 | G6: 자동화완 | H6: 진행률 | I6: 자동화 X
C7: 주행 중 녹화 기능 | D7: {=COUNTIF(INDIRECT("'"&C7&"'!A:A"),"OWD_*")-1} -> 145 | E7: =COUNTA(INDIRECT("'"&C7&"'!G:G"))-1 -> 362 | F7: =COUNTIF(INDIRECT("'"&C7&"'!Q:Q"),"△") -> 24 | G7: {=COUNTIF(INDIRECT("'"&C7&"'!Q:Q"),"01_OWD_*")} -> 145 | H7: =G7/E7 -> 0.40055249 | I7: =E7-G7 -> 217
C8: 주차 후 녹화 기능 | D8: {=COUNTIF(INDIRECT("'"&C8&"'!A:A"),"OWP_*")-1} -> 176 | E8: =COUNTA(INDIRECT("'"&C8&"'!G:G"))-1 -> 312 | F8: =COUNTIF(INDIRECT("'"&C8&"'!Q:Q"),"△") -> 22 | G8: {=COUNTIF(INDIRECT("'"&C8&"'!Q:Q"),"02_OWP_*")} -> 122 | H8: =G8/E8 -> 0.39102564 | I8: =E8-G8 -> 190
C9: HU 연동기능 | D9: {=COUNTIF(INDIRECT("'"&C9&"'!A:A"),"HU_*")-1} -> 218 | E9: =COUNTA(INDIRECT("'"&C9&"'!G:G"))-1 -> 326 | F9: =COUNTIF(INDIRECT("'"&C9&"'!Q:Q"),"△") -> 0 | G9: {=COUNTIF(INDIRECT("'"&C9&"'!Q:Q"),"03_HU_*")} -> 141 | H9: =G9/E9 -> 0.43251534 | I9: =E9-G9 -> 185
C10: 보조배터리 연동기능 | D10: {=COUNTIF(INDIRECT("'"&C10&"'!A:A"),"BAT_*")-1} -> 256 | E10: =COUNTA(INDIRECT("'"&C10&"'!G:G"))-1 -> 520 | F10: =COUNTIF(INDIRECT("'"&C10&"'!Q:Q"),"△") -> 51 | G10: {=COUNTIF(INDIRECT("'"&C10&"'!Q:Q"),"04_BAT_*")} -> 397 | H10: =G10/E10 -> 0.76346154 | I10: =E10-G10 -> 123
C11: 모바일 앱 연동기능 | D11: {=COUNTIF(INDIRECT("'"&C11&"'!A:A"),"APP_*")-1} -> 72 | E11: =COUNTA(INDIRECT("'"&C11&"'!G:G"))-1 -> 109 | F11: =COUNTIF(INDIRECT("'"&C11&"'!Q:Q"),"△") -> 0 | G11: 0 | H11: =G11/E11 -> 0 | I11: =E11-G11 -> 109
C12: DCM 연동기능 | D12: {=COUNTIF(INDIRECT("'"&C12&"'!A:A"),"DCM_*")-1} -> 239 | E12: =COUNTA(INDIRECT("'"&C12&"'!G:G"))-1 -> 727 | F12: =COUNTIF(INDIRECT("'"&C12&"'!Q:Q"),"△") -> 0 | G12: {=COUNTIF(INDIRECT("'"&C12&"'!Q:Q"),"11_DCM_*")} -> 215 | H12: =G12/E12 -> 0.2957359 | I12: =E12-F12 -> 727
C13: 표시 관련 서비스 | D13: {=COUNTIF(INDIRECT("'"&C13&"'!A:A"),"IND_*")-1} -> 42 | E13: =COUNTA(INDIRECT("'"&C13&"'!G:G"))-1 -> 105 | F13: =COUNTIF(INDIRECT("'"&C13&"'!Q:Q"),"△") -> 2 | G13: {=COUNTIF(INDIRECT("'"&C13&"'!Q:Q"),"05_IND_*")} -> 57 | H13: =G13/E13 -> 0.54285714 | I13: =E13-G13 -> 48
C14: 커넥티드 관련 서비스 | D14: {=COUNTIF(INDIRECT("'"&C14&"'!A:A"),"CCS_*")-1} -> 84 | E14: =COUNTA(INDIRECT("'"&C14&"'!G:G"))-1 -> 105 | F14: =COUNTIF(INDIRECT("'"&C14&"'!Q:Q"),"△") -> 1 | G14: {=COUNTIF(INDIRECT("'"&C14&"'!Q:Q"),"06_CCS_*")} -> 84 | H14: =G14/E14 -> 0.8 | I14: =E14-G14 -> 21
C15: 차량정보 저장기능 | D15: {=COUNTIF(INDIRECT("'"&C15&"'!A:A"),"INF_*")-1} -> 129 | E15: =COUNTA(INDIRECT("'"&C15&"'!G:G"))-1 -> 253 | F15: =COUNTIF(INDIRECT("'"&C15&"'!Q:Q"),"△") -> 0 | G15: 0 | H15: =G15/E15 -> 0 | I15: =E15-G15 -> 253
C16: 파일 재생 및 편집 | D16: {=COUNTIF(INDIRECT("'"&C16&"'!A:A"),"FIL_*")-1} -> 57 | E16: =COUNTA(INDIRECT("'"&C16&"'!G:G"))-1 -> 59 | F16: =COUNTIF(INDIRECT("'"&C16&"'!Q:Q"),"△") -> 0 | G16: 0 | H16: =G16/E16 -> 0 | I16: =E16-G16 -> 59
C17: 저장메모리 및 파일관리 | D17: {=COUNTIF(INDIRECT("'"&C17&"'!A:A"),"MEM_*")-1} -> 272 | E17: =COUNTA(INDIRECT("'"&C17&"'!G:G"))-1 -> 422 | F17: =COUNTIF(INDIRECT("'"&C17&"'!Q:Q"),"△") -> 0 | G17: 0 | H17: =G17/E17 -> 0 | I17: =E17-G17 -> 422
C18: 녹화 외 기본기능 | D18: {=COUNTIF(INDIRECT("'"&C18&"'!A:A"),"BAS_*")-1} -> 32 | E18: =COUNTA(INDIRECT("'"&C18&"'!G:G"))-1 -> 59 | F18: =COUNTIF(INDIRECT("'"&C18&"'!Q:Q"),"△") -> 0 | G18: {=COUNTIF(INDIRECT("'"&C18&"'!Q:Q"),"07_BAS_*")} -> 25 | H18: =G18/E18 -> 0.42372881 | I18: =E18-G18 -> 34
C19: 동작 성능 | D19: {=COUNTIF(INDIRECT("'"&C19&"'!A:A"),"PER_*")-1} -> 173 | E19: =COUNTA(INDIRECT("'"&C19&"'!G:G"))-1 -> 370 | F19: =COUNTIF(INDIRECT("'"&C19&"'!Q:Q"),"△") -> 46 | G19: {=COUNTIF(INDIRECT("'"&C19&"'!Q:Q"),"08_PER_*")} -> 201 | H19: =G19/E19 -> 0.54324324 | I19: =E19-G19 -> 169
C20: 비기능 외 | D20: {=COUNTIF(INDIRECT("'"&C20&"'!A:A"),"ETC_*")-1} -> 84 | E20: =COUNTA(INDIRECT("'"&C20&"'!G:G"))-1 -> 356 | F20: =COUNTIF(INDIRECT("'"&C20&"'!Q:Q"),"△") -> 0 | G20: {=COUNTIF(INDIRECT("'"&C20&"'!Q:Q"),"09_ETC_*")} -> 300 | H20: =G20/E20 -> 0.84269663 | I20: =E20-G20 -> 56
C21: 진단서비스 (1) | D21: {=COUNTIF(INDIRECT("'"&C21&"'!A:A"),"DIA_*")-1} -> 199 | E21: =COUNTA(INDIRECT("'"&C21&"'!G:G"))-1 -> 412 | F21: =COUNTIF(INDIRECT("'"&C21&"'!Q:Q"),"△") -> 12 | G21: {=COUNTIF(INDIRECT("'"&C21&"'!Q:Q"),"10_DIA1_*")} -> 255 | H21: =G21/E21 -> 0.61893204 | I21: =E21-G21 -> 157
C22: 진단서비스 (2) | D22: {=COUNTIF(INDIRECT("'"&C22&"'!A:A"),"DIA2_*")-1} -> 226 | E22: =COUNTA(INDIRECT("'"&C22&"'!G:G"))-1 -> 902 | F22: =COUNTIF(INDIRECT("'"&C22&"'!Q:Q"),"△") -> 0 | G22: {=COUNTIF(INDIRECT("'"&C22&"'!Q:Q"),"10_DIA2_*")} -> 902 | H22: =G22/E22 -> 1 | I22: =E22-G22 -> 0
C23: 진단서비스 (3) | D23: {=COUNTIF(INDIRECT("'"&C23&"'!A:A"),"DIA3_*")-1} -> 426 | E23: =COUNTA(INDIRECT("'"&C23&"'!G:G"))-1 -> 1499 | F23: =COUNTIF(INDIRECT("'"&C23&"'!Q:Q"),"△") -> 0 | G23: {=COUNTIF(INDIRECT("'"&C23&"'!Q:Q"),"10_DIA3_*")} -> 1499 | H23: =G23/E23 -> 1 | I23: =E23-G23 -> 0
C24: Sleep | D24: {=COUNTIF(INDIRECT("'"&C24&"'!A:A"),"Sleep_*")-1} -> 105 | E24: =COUNTA(INDIRECT("'"&C24&"'!G:G"))-1 -> 1096 | F24: =COUNTIF(INDIRECT("'"&C24&"'!Q:Q"),"△") -> 0 | G24: {=COUNTIF(INDIRECT("'"&C24&"'!Q:Q"),"Sleep_*")} -> 1096 | H24: =G24/E24 -> 1 | I24: =E24-G24 -> 0
C25: Wakeup | D25: {=COUNTIF(INDIRECT("'"&C25&"'!A:A"),"Wakeup_*")-1} -> 64 | E25: =COUNTA(INDIRECT("'"&C25&"'!G:G"))-1 -> 714 | F25: =COUNTIF(INDIRECT("'"&C25&"'!Q:Q"),"△") -> 0 | G25: {=COUNTIF(INDIRECT("'"&C25&"'!Q:Q"),"Wakeup_*")} -> 714 | H25: =G25/E25 -> 1 | I25: =E25-G25 -> 0
C26: Total | D26: =SUM(D7:D25) -> 2999 | E26: =SUM(E7:E25) -> 8708 | F26: =SUM(F7:F25) -> 158 | G26: =SUM(G7:G25) -> 6153 | H26: =G26/E26 -> 0.70659164 | I26: =E26-G26 -> 2555
K28: 자동화 합계 | L28: 자동화율 (목표) | M28: 자동화율 (현재)
K29: =SUM(F26:G26) -> 6311 | L29: =K29/E26 -> 0.72473588 | M29: =G26/E26 -> 0.70659164

Sheet 매크로 실행
B2: 1. 자동화 검증 결과 | J2: 2. 사양 필터링 | M2: 3. 송부본 만들기
J11: 사양 선택
J12: DCM_연동 X
J16: 사양구분
J17: CAN사양_CAN
J18: CAN사양_CANFD
J19: 주차 중 동작 감지 지원
J20: OTA_HU기반
J21: OTA_CCU기반
J22: 주차 중 상시 녹화 전원_보조배터리
J23: 주차 중 상시 녹화 전원_eAGM
J24: 주차 중 상시 녹화 전원_LFP
J25: 주차 중 상시 녹화 전원_eAGM_PLBM
... J35: 공차보정_지원

Sheet 매크로 사용법
B2: 1. 매크로 기능 활성화
B45: 2. 매크로 기능 사용하기
B77: 3. 매크로 함수 수정
B78: 송부용으로 만들기 : 송부본 만들 시 사용되는 각 함수 포함
B79: 표지에있는매크로버튼 : 송부용_만들기 / 선택한사양_제외하기 / 자동화_풀검증 / 자동화_기본 검증
B80: ※ [송부용으로 만들기] 모듈에서 함수 추가 시에는 [표지에있는매크로버튼] 모듈에서 [송부용_만들기] 함수에서 Call 명령어로 함수 불러와야함

Sheet 테스트케이스 작성 주의사항
B4: 1. 엑셀 시트 이름/띄어쓰기 변경 하지 말것
B5: ※ 엑셀 시트 이름/띄어쓰기 OR 시트 추가 시에는 매크로 수정 필요
B8: 2. 열 삭제/추가 변경하지 말 것
B9: ※ 변경 시, 매크로 수정 필요
B12: 3. 2행에 있는 이름/띄어쓰기 변경 하지 말것
B13: ※ 변경 시, 매크로 수정필요
B16: <<신규 테스트 케이스 작성 주의 사항>>
B18: 1. 기존의 작성된 TC ID는 수정하지 말 것
B19: ※ 추적성 꺠짐 (ALM)
B21: 2. B1에 현재 작성된 TC ID 중 제일 큰 값 확인할 수 있으며, 해당 값 보다 증가하여 TC ID 부여할 것
B39: 3. Step 비어있는 값 없도록 확인할 것
B41: 4. 사양 구분 확인 할것
B42: ※ 신규 사양 구분 카테고리면 매크로 실행 탭에서 수정할 것

Sheet 주행 중 녹화 기능
A1: {="OWD_"&TEXT(MAX(IFERROR(--MID($A$2:$A$4981,5,3),0)),"000")} -> OWD_145 | D1: English Translation | E1: English Translation | F1: English Translation | H1: English Translation | I1: English Translation
A2: ID | B2: Test method | C2: TC design method | D2: Verification items | E2: detail | F2: Precondition | G2: Step | H2: Execution Procedure | I2: Expected value | J2: 결과 | K2: 측정값 | L2: 판정 | M2: 비고 | O2: 매뉴얼 기본 | P2: 자동화 기본 | Q2: 자동화 반영 | R2: 사양구분 | S2: 과거차문제
A3: [BLTN_CAM-기능-001] 주행 중 상시 녹화
A4: OWD_001 | B4: ▪ Requirement-based test | C4: ▪ Requirements Analysis | D4: [Continuous recording while driving] - (1) | E4: Check default values ​​for continuous recording settings while driving | F4: ▪ Built-in Cam Boot Complete ▪ BLTN_CAM_State = 0x0 (BLTN_CAM Valid) ▪ BLTN_CAM_SD_Card_State = 0x0 (Good) ▪ Associated Controller CAN/Ethernet Communication Enabled ▪ Power: Key On ▪ Voltage: 12V | G4: 1 | H4: ▪ ICU_PowerAutoCutModSta = 0x0(Factory mode) → 0x2(Customer mode) ※ Automatically deletes all videos and resets settings when changing from Factory Mode/Transport (Dealer) Mode to Customer Mode | I4: ▪ BLTN_CAM_RecSet_OWD = 0x1(Off) | J4: Pass | O4: O | P4: X | Q4: 01_OWD_001, 01_OWD_002
G5: 2 | H5: ▪ [ccNC Settings] - [General] - [Initialization] - [Full System Initialization] | I5: ▪ BLTN_CAM_RecSet_OWD = 0x1(Off) | J5: Pass | O5: O | P5: X | Q5: 01_OWD_001, 01_OWD_002
G6: 3 | H6: ▪ First Run Setup (FRS) completed in HU (BLTN_CAM_Rec_OWD_NvalueSet / BLTN_CAM_Rec_DEV_NvalueSet / BLTN_CAM_Rec_OWP_NvalueSet / BLTN_CAM_Rec_PEV_NvalueSet = 0x2 (On) transmitted) | I6: ▪ Domestic/Japan/North America/Russia/Middle East BLTN_CAM_RecSet_OWD = 0x2(On) : Apply FRS ▪ Europe BLTN_CAM_RecSet_OWD = 0x1(Off) : Initial value | J6: Pass | O6: O | P6: X | Q6: 01_OWD_001, 01_OWD_002
G7: 4 | H7: ▪ [ccNC Settings] - [General] - [Initialization] - [Full System Initialization] | I7: ▪ Domestic/Japan/North America/Russia/Middle East BLTN_CAM_RecSet_OWD = 0x2(On) : The default recording setting is On when initialized after FRS setup operation ▪ Europe BLTN_CAM_RecSet_OWD = 0x1(Off) : The default recording setting is Off when initialized after FRS setup operation | J7: Pass | O7: O | P7: X | Q7: 01_OWD_001, 01_OWD_002
A8: OWD_002 | B8: ▪ Requirement-based test | C8: ▪ Requirements Analysis | D8: [Continuous Recording While Driving] - (2) | E8: Confirmation that continuous recording while driving does not operate in BLTN_CAM mode | F8: ▪ Built-in Cam Boot Complete ▪ BLTN_CAM_State = 0x0 (BLTN_CAM Valid) ▪ BLTN_CAM_SD_Card_State = 0x0 (Good) ▪ Associated Controller CAN/Ethernet Communication Enabled ▪ Power: Key On ▪ Voltage: 12V ▪ Setting: Continuous Recording While Driving ON | G8: 1 | H8: ▪HU_BLTN_CAM_UI_Mode = 0x1 (BLTN_CAM mode) ▪ Check recording status signal | I8: ▪ BLTN_CAM_HU_UI_Mode = 0x1 (BLTN_CAM mode) ▪ BLTN_CAM_RecSta_OWD = 0x0(Off) | J8: Pass | O8: O | P8: 00_1CHK_215 | Q8: 01_OWD_003
G9: 2 | H9: ▪ Check front/rear camera indicator | I9: ▪Camera Indicator (Blink Cycle/Duty Ratio/Hold Time) - Off/-/Hold | O9: O | P9: △ | Q9: △
G10: 3 | H10: ▪ Check event switch indicator | I10: ▪Event Switch Indicator (Blink Cycle/Duty Ratio/Hold Time) - Off/-/Hold | J10: Pass | O10: O | P10: 00_1CHK_215 | Q10: 01_OWD_003
A11: OWD_052 | B11: ▪ Requirement-based test | C11: ▪ Requirements Analysis | D11: [Continuous Recording While Driving] - (2) | E11: Confirmation that continuous recording while driving does not work in Engineer mode | F11: ▪ Built-in Cam Boot Complete ▪ BLTN_CAM_State = 0x0 (BLTN_CAM Valid) ▪ BLTN_CAM_SD_Card_State = 0x0 (Good) ▪ Associated Controller CAN/Ethernet Communication Enabled ▪ Power: Key On ▪ Voltage: 12V ▪ Setting: Continuous Recording While Driving ON | G11: 1 | H11: ▪ BLTN_CAM_LVDS_Mode_Cmd = 0x2 (Engineer mode) ▪ Check recording status signal | I11: ▪ BLTN_CAM_LVDS_Mode_State = 0X2 (Engineer mode) ▪ BLTN_CAM_RecSta_OWD = 0x0(Off) | J11: Pass | O11: X | P11: 00_1CHK_216 | Q11: 01_OWD_004
G12: 2 | H12: ▪ Check front/rear camera indicator | I12: ▪Camera Indicator (Blink Cycle/Duty Ratio/Hold Time) - Off/-/Hold | O12: X | P12: △ | Q12: △
G13: 3 | H13: ▪ Check event switch indicator | I13: ▪Event Switch Indicator (Blink Cycle/Duty Ratio/Hold Time) - Off/-/Hold | J13: Pass | O13: X | P13: 00_1CHK_216 | Q13: 01_OWD_004
A14: OWD_053 | B14: ▪ Requirement-based test | C14: ▪ Requirements Analysis | D14: [Continuous Recording While Driving] - (2) | E14: Check recording operation in HU mode (IGN power) | F14: ▪ Built-in Cam Boot Complete ▪ BLTN_CAM_State = 0x0 (BLTN_CAM Valid) ▪ BLTN_CAM_SD_Card_State = 0x0 (Good) ▪ Associated Controller CAN/Ethernet Communication Enabled ▪ Power: ACC OFF, IGN ON ▪ Voltage: 12V ▪ Setting: Continuous Recording While Driving ON | G14: 1 | H14: ▪ Switch HU screen ▪ Check recording status signal | I14: ▪ BLTN_CAM_RecSta_OWD = 0x1(Recoreding) ※ The signal delay between the actual recording time and the actual recording time will be 1 second. | J14: Pass | O14: X | P14: 00_1CHK_217 | Q14: 01_OWD_005
G15: 2 | H15: ▪ Check the time taken to start recording (In Built-in Cam mode, the time is measured by the stopwatch as soon as the HOME button is pressed, and recorded as the time captured in the recording file) | I15: ▪ Recording starts within 4 seconds of exiting Built-in Cam mode | O15: X | P15: X | Q15: X
G16: 3 | H16: ▪ Check front/rear camera indicator | I16: ▪ Camera Indicator (Blink Cycle/Duty Ratio/Hold Time) - 0.5Hz/50%/Hold | O16: X | P16: △ | Q16: △
G17: 4 | H17: ▪ Check event switch indicator | I17: ▪Event Switch Indicator (Blink Cycle/Duty Ratio/Hold Time) - On/100%/Hold | J17: Pass | O17: X | P17: 00_1CHK_217 | Q17: 01_OWD_005
A18: OWD_054 | B18: ▪ Requirement-based test | C18: ▪ Requirements Analysis | D18: [Continuous Recording While Driving] - (2) | E18: Check recording operation in HU mode (ACC power) | F18: ▪ Built-in Cam Boot Complete ▪ BLTN_CAM_State = 0x0 (BLTN_CAM Valid) ▪ BLTN_CAM_SD_Card_State = 0x0 (Good) ▪ Associated Controller CAN/Ethernet Communication Enabled ▪ Power: ACC ON, IGN OFF ▪ Voltage: 12V ▪ Setting: Continuous Recording While Driving ON | G18: 1 | H18: ▪ Enter Built-in Cam Mode, stop recording, and exit. ▪ Check recording status signal. | I18: ▪ BLTN_CAM_RecSta_OWD = 0x1(Recoreding) | J18: Pass | O18: X | P18: 00_1CHK_218 | Q18: 01_OWD_006
G19: 2 | H19: ▪ Check the time taken to start recording (In Built-in Cam mode, the time is measured by the stopwatch as soon as the HOME button is pressed, and recorded as the time captured in the recording file) | I19: ▪ Recording starts within 4 seconds of exiting Built-in Cam mode | O19: X | P19: X | Q19: X
G20: 3 | H20: ▪ Check front/rear camera indicator | I20: ▪ Camera Indicator (Blink Cycle/Duty Ratio/Hold Time) - 0.5Hz/50%/Hold | O20: X | P20: △ | Q20: △
G21: 4 | H21: ▪ Check event switch indicator | I21: ▪Event Switch Indicator (Blink Cycle/Duty Ratio/Hold Time) - On/100%/Hold | J21: Pass | O21: X | P21: 00_1CHK_218 | Q21: 01_OWD_006
A22: OWD_034 | B22: ▪ Requirement-based test | C22: ▪ Requirements Analysis | D22: [Performance Recording] - (1) | E22: Check Performance Recording Signal Initial Value | F22: ▪ Built-in Cam Boot Complete ▪ BLTN_CAM_State = 0x0 (BLTN_CAM Valid) ▪ BLTN_CAM_SD_Card_State = 0x0 (Good) ▪ Associated Controller CAN/Ethernet Communication Enabled ▪ Power: Key On ▪ Voltage: 12V | G22: 1 | H22: ▪ ICUPowerAutoCutMode = 0x0(Factory mode) → 0x2(Customer mode) ▪ Built-in Cam Main Screen ▪ [ccNC Settings] - [General] - [Reset] - [Delete Guest Profile / Reset System] - Check Default Values | I22: ▪ BLTN_CAM_RecSta_BPR = 0x1(Off) | O22: X | P22: X | Q22: X | R22: 퍼포먼스_지원
A23: OWD_035 | B23: ▪ Requirement-based test | C23: ▪ Requirements Analysis | D23: [Performance Recording] - (2) | E23: Verify performance recording operation in N mode | F23: ▪ Built-in Cam Boot Complete ▪ BLTN_CAM_State = 0x0 (BLTN_CAM Valid) ▪ BLTN_CAM_SD_Card_State = 0x0 (Good) ▪ Associated Controller CAN/Ethernet Communication Enabled ▪ Power: Key On ▪ Voltage: 12V | G23: 1 | H23: ▪HU_BLTN_CAM_UI_Mode = 0x1 (BLTN_CAM mode) ▪ Enter N mode within HU ▪ Touch "REC" on N Race Cam to start recording ▪ Check performance recording status signal | I23: ▪ BLTN_CAM_HU_UI_Mode = 0x0 (HU UI mode) ▪ BLTN_CAM_RecSta_BPR = 0x1 (Recording) | O23: X | P23: X | Q23: X | R23: 퍼포먼스_지원
G24: 2 | H24: ▪ Check front/rear camera indicator | I24: ▪ Camera Indicator (Blink Cycle/Duty Ratio/Hold Time) - 0.5Hz/50%/Hold | O24: X | P24: X | Q24: X | R24: 퍼포먼스_지원
G25: 3 | H25: ▪ Check event switch indicator | I25: ▪ Event Switch Indicator (Blink Cycle/Duty Ratio/Hold Time) - On/-/Hold | O25: X | P25: X | Q25: X | R25: 퍼포먼스_지원
G26: 4 | H26: ▪ Enter Performance Options ▪ Check the recording status of the N Race Cam "REC" button among the items | I26: ▪ Performance recording proceeds without interruption (Recording count confirmed and recording indicator red confirmed) | O26: X | P26: X | Q26: X | R26: 퍼포먼스_지원
G27: 5 | H27: ▪ Touch the N Race Cam "File" button among the items | I27: ▪ BLTN_CAM_RecSta_BPR = 0x0 (Off) ▪ Move to Built-in Cam Video Save List | O27: X | P27: X | Q27: X | R27: 퍼포먼스_지원
G28: 6 | H28: ▪ Check front/rear camera indicator | I28: ▪ Camera Indicator (Flash Cycle/Duty Ratio/Hold Time) - Off/-/Hold | O28: X | P28: X | Q28: X | R28: 퍼포먼스_지원
G29: 7 | H29: ▪ Check event switch indicator | I29: ▪ Event Switch Indicator (Blink Cycle/Duty Ratio/Hold Time) - On/100%/Hold | O29: X | P29: X | Q29: X | R29: 퍼포먼스_지원
A30: OWD_055 | B30: ▪ Requirement-based test | C30: ▪ Requirements Analysis | D30: [Performance Recording] - (2) | E30: Verify recording operation in HU mode | F30: ▪ Built-in Cam Boot Complete ▪ BLTN_CAM_State = 0x0 (BLTN_CAM Valid) ▪ BLTN_CAM_SD_Card_State = 0x0 (Good) ▪ Associated Controller CAN/Ethernet Communication Enabled ▪ Power: Key On ▪ Voltage: 12V | G30: 1 | H30: ▪HU_BLTN_CAM_UI_Mode = 0x1 (BLTN_CAM mode) ▪ Enter N Mode within HU ▪ Touch "REC" on N Race Cam to start recording ▪ Switch from N Mode to HU screen ▪ Check recording status signal | I30: ▪BLTN_CAM_HU_UI_Mode = 0x0 (HU UI mode) ▪ BLTN_CAM_RecSta_BPR = 0x1 (Recording) | O30: X | P30: X | Q30: X | R30: 퍼포먼스_지원
G31: 2 | H31: ▪ Check front/rear camera indicator | I31: ▪ Camera Indicator (Blink Cycle/Duty Ratio/Hold Time) - 0.5Hz/50%/Hold | O31: X | P31: X | Q31: X | R31: 퍼포먼스_지원
G32: 3 | H32: ▪ Check event switch indicator | I32: ▪ Event Switch Indicator (Blink Cycle/Duty Ratio/Hold Time) - On/100%/Hold | O32: X | P32: X | Q32: X | R32: 퍼포먼스_지원
G33: 4 | H33: ▪ Check the indicator on the display | I33: ▪ Indicator displayed during recording | O33: X | P33: X | Q33: X | R33: 퍼포먼스_지원
A34: OWD_056 | B34: ▪ Requirement-based test | C34: ▪ Requirements Analysis | D34: [Performance Recording] - (2) | E34: Confirmation of non-operation of performance recording in BLTN_CAM mode | F34: ▪ Built-in Cam Boot Complete ▪ BLTN_CAM_State = 0x0 (BLTN_CAM Valid) ▪ BLTN_CAM_SD_Card_State = 0x0 (Good) ▪ Associated Controller CAN/Ethernet Communication Enabled ▪ Power: Key On ▪ Voltage: 12V | G34: 1 | H34: ▪HU_BLTN_CAM_UI_Mode = 0x1 (BLTN_CAM mode) ▪ Enter N mode within HU ▪ Touch "REC" to start recording on N Race Cam ▪ Enter Built-in Cam ▪ Check recording status signal | I34: ▪ BLTN_CAM_HU_UI_Mode = 0x0 (HU UI mode) ▪ BLTN_CAM_RecSta_BPR = 0x0 (Off) | O34: X | P34: X | Q34: X | R34: 퍼포먼스_지원
G35: 2 | H35: ▪ Check front/rear camera indicator | I35: ▪ Camera Indicator (Blink Cycle/Duty Ratio/Hold Time) - Off/-/Hold | O35: X | P35: X | Q35: X | R35: 퍼포먼스_지원
G36: 3 | H36: ▪ Check event switch indicator | I36: ▪ Event Switch Indicator (Blink Cycle/Duty Ratio/Hold Time) - Off/-/Hold | O36: X | P36: X | Q36: X | R36: 퍼포먼스_지원
G37: 4 | H37: ▪ Check the indicator on the display | I37: ▪ Indicator not showing recording | O37: X | P37: X | Q37: X | R37: 퍼포먼스_지원
A38: OWD_003 | B38: ▪ Requirement-based test | C38: ▪ Requirements Analysis | D38: [Continuous Recording While Driving] - (3) | E38: Verify that the continuous recording setting is ON while driving. | F38: ▪ Built-in Cam Boot Complete ▪ BLTN_CAM_State = 0x0 (BLTN_CAM Valid) ▪ BLTN_CAM_SD_Card_State = 0x0 (Good) ▪ Associated Controller CAN/Ethernet Communication Enabled ▪ Power: Key On ▪ Voltage: 12V ▪ Setting: Continuous Recording While Driving ON | G38: 1 | H38: ▪ 3-Minute Standby ▪ Built-in Cam Main Screen ▪ [Always On While Driving] Check Storage Box | I38: ▪ No black thumbnails in the video list ▪ Displayed in the video list by the start time of continuous recording while driving ▪ Three videos (Front + Rear 60 sec) combined and displayed as a single group in the HU | O38: X | P38: X | Q38: X
G39: 2 | H39: ▪ Playback of recording files generated in HU | I39: ▪ No video glitches, green screens, black screens, or noise | O39: X | P39: X | Q39: X
G40: 3 | H40: ▪ Check left and right sides of the generated recording file video | I40: ▪ No horizontal flip of the video | O40: X | P40: X | Q40: X
...

Sheet 주차 후 녹화 기능
A1: {="OWP_"&TEXT(MAX(IFERROR(--MID($A$2:$A$5024,5,3),0)),"000")} -> OWP_225 | D1: English Translation | E1: English Translation | F1: English Translation | H1: English Translation | I1: English Translation
A2: ID | B2: Test method | C2: TC design method | D2: Verification items | E2: detail | F2: Precondition | G2: Step | H2: Execution Procedure | I2: Expected value | J2: 결과 | K2: 측정값 | L2: 판정 | M2: 비고 | O2: 매뉴얼 기본 | P2: 자동화 기본 | Q2: 자동화 반영 | R2: 사양구분 | S2: 과거차문제
A3: [BLTN_CAM-기능-005] 주차 상시 녹화
A4: OWP_001 | B4: ▪ Requirement-based test | C4: ▪ Requirements Analysis | D4: [Continuous recording while parked] | E4: Check default values ​​for continuous recording settings while parked | F4: ▪ Built-in Cam Boot Complete ▪ BLTN_CAM_State = 0x0 (BLTN_CAM Valid) ▪ BLTN_CAM_SD_Card_State = 0x0 (Good) ▪ Associated Controller CAN/Ethernet Communication Enabled ▪ Power: Key ON ▪ Voltage: 12V | G4: 1 | H4: ▪ ICU_PowerAutoCutModSta = 0x0(Factory mode) → 0x2(Customer mode) ※ Automatically deletes all videos and resets settings when changing from Factory Mode/Dealer Mode to Customer Mode | I4: ▪ Check default settings after factory reset - Domestic/Japan: Always-on recording while parked OFF, Event recording while parked OFF, Event notification while parked ON - Europe: Always-on recording while parked Default, Event recording while parked OFF, Event notification while parked OFF - Middle East/North America/Russia: Always-on recording while parked OFF, Event recording while parked OFF, Event notification while parked Default ※ Exception: Always-on recording while parked / Event recording while parked applied to JG1 RUS | J4: Pass | O4: O | P4: X | Q4: 02_OWP_001, 02_OWP_002, 02_OWP_072 | R4: 주차 중 상시 녹화_지원
G5: 2 | H5: ▪ [ccNC Settings] - [General] - [Initialization] - [Full System Initialization] | I5: ▪ Domestic/Japan/North America: Continuous Recording while parked OFF, Event Recording while parked OFF, Event Notification while parked ON ▪ Europe: Continuous Recording while parked Default, Event Recording while parked OFF, Event Notification while parked OFF ▪ Russia/Middle East: Continuous Recording while parked OFF, Event Recording while parked OFF, Event Notification while parked Default ※ Continuous Recording while parked and Event Recording while parked are applied as an exception for JG1 RUS | J5: Pass | O5: O | P5: X | Q5: 02_OWP_001, 02_OWP_002, 02_OWP_072 | R5: 주차 중 상시 녹화_지원
G6: 3 | H6: ▪ First Run Setup (FRS) completed in HU (BLTN_CAM_Rec_OWD_NvalueSet / BLTN_CAM_Rec_DEV_NvalueSet / BLTN_CAM_Rec_OWP_NvalueSet / BLTN_CAM_Rec_PEV_NvalueSet = 0x2 (ON) transmitted) | I6: ▪ Domestic/Japan/North America BLTN_CAM_RecSet_OWP = 0x2(ON) ▪ Europe/Russia/Middle East BLTN_CAM_RecSet_OWP = 0x0(Default) ※ Continuous recording while parked/Event recording while parked applied as an exception for JG1 RUS | J6: Pass | O6: O | P6: X | Q6: 02_OWP_003, 02_OWP_004 | R6: 주차 중 상시 녹화_지원
G7: 4 | H7: ▪ [ccNC Settings] - [General] - [Initialization] - [Full System Initialization] | I7: ▪ Domestic/Japan/North America BLTN_CAM_RecSet_OWP = 0x2(ON) : The default recording setting is ON upon initialization after FRS setup operation. ▪ Europe/Russia/Middle East BLTN_CAM_RecSet_OWP = 0x0(Default) : The default recording setting is Default upon initialization after FRS setup operation. ※ Continuous recording while parked / Event recording while parked applied as an exception for JG1 RUS. | J7: Pass | O7: O | P7: X | Q7: 02_OWP_003, 02_OWP_004 | R7: 주차 중 상시 녹화_지원
G8: 5 | H8: ▪ [Settings] - [Event Detection Sensitivity] - Check Recording While Parked | I8: ▪ Domestic/Japan/North America/Europe BLTN_CAM_SenSet_PEV = 0x3(Lv.3) ▪ Russia/Middle East BLTN_CAM_SenSet_PEV = 0x0(Default) ※ Continuous recording while parked/Event recording while parked applied as an exception for JG1 RUS | J8: Pass | O8: O | P8: X | Q8: 02_OWP_005, 02_OWP_006 | R8: 주차 중 상시 녹화_지원
G9: 6 | H9: ▪ [Recording while parked] - [Recording time while parked] - Check initial value | I9: ▪ Domestic/Japan/North America/Europe BLTN_CAM_Set_PrkTime = 0x14(20Hr) ▪ Russia/Middle East BLTN_CAM_Set_PrkTime = 0x0(Default) ※ Continuous recording while parked/Event recording while parked applied as an exception for JG1 RUS | J9: Pass | O9: O | P9: X | Q9: 02_OWP_005, 02_OWP_006 | R9: 주차 중 상시 녹화_지원
A10: OWP_026 | B10: ▪ Requirement-based test | C10: ▪ Requirements Analysis | D10: [Continuous recording while parked] | E10: Confirmation of continuous recording operation while parked : Domestic/Japan/North America | F10: ▪ Built-in Cam Boot Complete ▪ BLTN_CAM_State = 0x0 (BLTN_CAM Valid) ▪ BLTN_CAM_SD_Card_State = 0x0 (Good) ▪ Associated Controller CAN/Ethernet Communication Enabled ▪ Power: Key ON ▪ Voltage: 12V ▪ Setting: Continuous Recording While Parked ON | G10: 1 | H10: ▪ Key Off ▪ Check recording status signal | I10: ▪ BLTN_CAM_RecSta_OWP = 0x1(Recording) : The difference between the actual recording start time (check recording file) and the signal ON must be within 2 seconds. ▪ BLTN_CAM_RecSta_OWD = 0x0(OFF) ▪ No recording start delay (recording starts within 5 seconds based on GN7) | J10: Pass | O10: O | P10: 00_1CHK_156 | Q10: 02_OWP_007 | R10: 주차 중 상시 녹화_지원
G11: 2 | H11: ▪ Check front/rear camera indicator | I11: ▪ Camera Indicator 0.5Hz/50%/Maintain | O11: O | P11: △ | Q11: △ | R11: 주차 중 상시 녹화_지원
G12: 3 | H12: ▪ Check event switch indicator | I12: ▪ Event switch indicator ON/100%/Hold | J12: Pass | O12: O | P12: 00_1CHK_156 | Q12: 02_OWP_007 | R12: 주차 중 상시 녹화_지원
A13: OWP_028 | B13: ▪ Requirement-based test | C13: ▪ Requirements Analysis | D13: [Continuous Recording While Parked] Setting ON/OFF | E13: Confirmation that continuous parking recording is not applied : Middle East/Europe/Russia | F13: ▪ Built-in Cam Boot Complete ▪ BLTN_CAM_State = 0x0 (BLTN_CAM Valid) ▪ BLTN_CAM_SD_Card_State = 0x0 (Good) ▪ Associated Controller CAN/Ethernet Communication Enabled ▪ Power: Key ON ▪ Voltage: 12V | G13: 1 | H13: ▪ Enter Built-in Cam Mode ▪ [Settings] - [Recording] - [Recording While Parked] - Confirm No UI for Continuous Recording While Parked ▪ Check Recording Settings Signal | I13: ▪ No UI for continuous recording settings while parked ▪ BLTN_CAM_RecSet_OWP = 0x0(Defualt) | O13: O | P13: 02_OWP_011 | Q13: 02_OWP_011 | R13: 주차 중 상시 녹화_미지원
A14: OWP_002 | B14: ▪ Requirement-based test | C14: ▪ Requirements Analysis | D14: [Continuous Recording While Parked] Setting ON/OFF | E14: Confirmation of non-operation of recording when continuous parking recording is OFF | F14: ▪ Built-in Cam Boot Complete ▪ BLTN_CAM_State = 0x0 (BLTN_CAM Valid) ▪ BLTN_CAM_SD_Card_State = 0x0 (Good) ▪ Associated Controller CAN/Ethernet Communication Enabled ▪ Power: Key ON ▪ Voltage: 12V | G14: 1 | H14: ▪ Enter Built-in Cam Mode ▪ [Settings] - [Recording] - [Recording While Parked] - Turn Off Continuous Recording While Parked, Turn Off Event Recording While Parked ▪ (Vehicles with Motion Detection While Parked) [Settings] - [Recording] - [Recording While Parked] - Turn Off Motion Detection Recording While Parked | I14: ▪ BLTN_CAM_RecSet_OWP = 0x1(OFF) ▪ BLTN_CAM_RecSet_PEV = 0x1(OFF) ▪ BLTN_CAM_RecSet_PMD = 0x1(OFF) or 0x0(Default) | J14: Pass | O14: X | P14: 00_1CHK_158 | Q14: 02_OWP_009 | R14: 주차 중 상시 녹화_지원
G15: 2 | H15: ▪ Enter HU Mode ▪ Turn Key Off to enable continuous recording while parked ▪ Check recording status signal | I15: ▪ BLTN_CAM_RecSta_OWP = 0x0(OFF) | J15: Pass | O15: X | P15: 00_1CHK_159 | Q15: 02_OWP_010 | R15: 주차 중 상시 녹화_지원
G16: 3 | H16: ▪ Check front/rear camera indicator | I16: ▪ Camera Indicator OFF/-/Keep | O16: X | P16: △ | Q16: △ | R16: 주차 중 상시 녹화_지원
G17: 4 | H17: ▪ Check event switch indicator | I17: ▪ Event switch indicator OFF/-/Hold | J17: Pass | O17: X | P17: 00_1CHK_159 | Q17: 02_OWP_010 | R17: 주차 중 상시 녹화_지원
A18: OWP_029 | B18: ▪ Requirement-based test | C18: ▪ Requirements Analysis | D18: [Continuous Recording While Parked] Setting ON/OFF | E18: Check BLTN_CAM_Prk_Oprable_Time : P-LBM | F18: ▪ Built-in Cam Boot Complete ▪ BLTN_CAM_State = 0x0 (BLTN_CAM Valid) ▪ BLTN_CAM_SD_Card_State = 0x0 (Good) ▪ Associated Controller CAN/Ethernet Communication Enabled ▪ Power: Key ON ▪ Voltage: 12V ▪ Setting: Parking Continuous Recording ON | G18: 1 | H18: ▪ Apply SOC abnormal status signal: P-LBM SoC: Transmit BAT_SOC_for_BLTN_CAM = 0xFF ▪ [Settings] - [Recording] - [Recording While Parked] - Turn on Continuous Recording ▪ Turn off the key to enter Continuous Recording While Parked | I18: ▪ BLTN_CAM_Prk_Oprable_Time = 0x00 | J18: Pass | O18: X | P18: X | Q18: 02_OWP_074 | R18: 주차 중 상시 녹화_지원
A19: OWP_030 | B19: ▪ Requirement-based test | C19: ▪ Requirements Analysis | D19: [Continuous Recording While Parked] Setting ON/OFF | E19: Check BLTN_CAM_Prk_Oprable_Time : eAGM | F19: ▪ Built-in Cam Boot Complete ▪ BLTN_CAM_State = 0x0 (BLTN_CAM Valid) ▪ BLTN_CAM_SD_Card_State = 0x0 (Good) ▪ Associated Controller CAN/Ethernet Communication Enabled ▪ Power: Key ON ▪ Voltage: 12V ▪ Setting: Parking Continuous Recording ON | G19: 1 | H19: ▪ Apply SOC abnormal status signal: Transmit ICU_BS2SoC = Invalid(0x65~0xFE) or Error (0xFF) ▪ [Settings] - [Recording] - [Recording While Parked] - Turn on Continuous Recording ▪ Turn off the key to enter Continuous Recording While Parked | I19: ▪ BLTN_CAM_Prk_Oprable_Time = 0x00 | J19: Pass | O19: X | P19: X | Q19: 02_OWP_074 | R19: 주차 중 상시 녹화_지원
A20: OWP_031 | B20: ▪ Requirement-based test | C20: ▪ Requirements Analysis | D20: [Continuous Recording While Parked] Setting ON/OFF | E20: Check BLTN_CAM_Prk_Oprable_Time : LFP | F20: ▪ Built-in Cam Boot Complete ▪ BLTN_CAM_State = 0x0 (BLTN_CAM Valid) ▪ BLTN_CAM_SD_Card_State = 0x0 (Good) ▪ Associated Controller CAN/Ethernet Communication Enabled ▪ Power: Key ON ▪ Voltage: 12V ▪ Setting: Parking Continuous Recording ON | G20: 1 | H20: ▪ Apply SOC abnormal status signal: Transmit BAT_SocVal = Error(0xFF) ▪ [Settings] - [Recording] - [Recording While Parked] - Turn on Continuous Recording ▪ Turn off the key to enter Continuous Recording While Parked | I20: ▪ BLTN_CAM_Prk_Oprable_Time = 0x00 | J20: Pass | O20: X | P20: X | Q20: 02_OWP_074 | R20: 주차 중 상시 녹화_지원
A21: OWP_032 | B21: ▪ Requirement-based test | C21: ▪ Requirements Analysis | D21: [Continuous Recording While Parked] Setting ON/OFF | E21: Check BLTN_CAM_Prk_Oprable_Time : M-LBM | F21: ▪ Built-in Cam Boot Complete ▪ BLTN_CAM_State = 0x0 (BLTN_CAM Valid) ▪ BLTN_CAM_SD_Card_State = 0x0 (Good) ▪ Associated Controller CAN/Ethernet Communication Enabled ▪ Power: Key ON ▪ Voltage: 12V | G21: 1 | H21: ▪ Apply SOC abnormal status signal: Transmit MainLBM_SocVal = Error(0xFF) ▪ [Settings] - [Recording] - [Recording While Parked] - Turn on Continuous Recording ▪ Turn off the key to enter Continuous Recording While Parked | I21: ▪ BLTN_CAM_Prk_Oprable_Time = 0x00 | J21: Pass | O21: X | P21: X | Q21: 02_OWP_074 | R21: 주차 중 상시 녹화_지원
A22: OWP_033 | B22: ▪ Requirement-based test ▪ Test derived from field experience | C22: ▪ Requirements Analysis ▪ Field Experience-based Testing | D22: [Continuous Recording While Parked] Setting ON/OFF | E22: Confirm recording file creation (3 minutes) - Create 1 3-minute recording file | F22: ▪ Built-in Cam Boot Complete ▪ BLTN_CAM_State = 0x0 (BLTN_CAM Valid) ▪ BLTN_CAM_SD_Card_State = 0x0 (Good) ▪ Associated Controller CAN/Ethernet Communication Enabled ▪ Power: Key ON ▪ Voltage: 12V | G22: 1 | H22: ▪ Enter Built-in Cam Mode ▪ [Settings] - [Recording] - [Recording While Parked] - Turn On Continuous Recording ▪ Turn Key Off to enter Continuous Recording While Parked ▪ Wait 3 minutes, then turn Key ON ▪ After entering Built-in Cam Mode, check the [Continuous Recording While Parked] box | I22: ▪ Confirmation of continuous recording file saving during parking: Verify creation of a list containing 1 file of front + rear video (3 min) ▪ No black thumbnails in the video list ▪ The recording start time should be displayed in the video list ▪ No video glitches, green screens, black screens, or noise ▪ The progress bar plays to the end during video playback | M22: 과거차문제 PASTI-340 주차 중 상시 녹화 진입 초기에 후방영상 블랙으로 저장 되며 간헐적으로 썸네일도 블랙 저장 | O22: O | P22: X | Q22: X | R22: 주차 중 상시 녹화_지원 | S22: O
A23: OWP_034 | B23: ▪ Requirement-based test ▪ Test derived from field experience | C23: ▪ Requirements Analysis ▪ Field Experience-based Testing | D23: [Continuous Recording While Parked] Setting ON/OFF | E23: [Conditions of Evil] Key ON/OFF Repeat quickly 20 times, then OFF | F23: ▪ Built-in Cam Boot Complete ▪ BLTN_CAM_State = 0x0 (BLTN_CAM Valid) ▪ BLTN_CAM_SD_Card_State = 0x0 (Good) ▪ Associated Controller CAN/Ethernet Communication Enabled ▪ Power: Key ON ▪ Voltage: 12V ▪ Setting: Parking Continuous Recording ON | G23: 1 | H23: ▪ Enter Built-in Cam Mode ▪ Quickly turn Key ON/OFF 20 times, then turn Key OFF to enter continuous recording while parked. (Real vehicle conditions: Quickly press the Engine Start button) ▪ Check recording status signal (Verify if continuous recording while parked has been entered) | I23: ▪ BLTN_CAM_RecSta_OWP = 0x1(Recording) | J23: Pass | O23: O | P23: X | Q23: 02_OWP_012 | R23: 주차 중 상시 녹화_지원 | S23: O
G24: 2 | H24: ▪ Check front/rear camera indicator | I24: ▪ Camera Indicator 0.5Hz/50%/Maintain | O24: O | P24: X | Q24: △ | R24: 주차 중 상시 녹화_지원 | S24: O
G25: 3 | H25: ▪ Check event switch indicator | I25: ▪ Event switch indicator ON/100%/Hold | O25: O | P25: X | Q25: △ | R25: 주차 중 상시 녹화_지원 | S25: O
G26: 4 | H26: ▪ Turn Key ON after waiting 1 minute ▪ After entering Built-in Cam mode, check the [Always On While Parked] box | I26: ▪ Verify that continuous recording files are saved while parked ▪ No black thumbnails in the video list ▪ Videos will be displayed in the list based on the recording start time ▪ No video glitches, green screens, black screens, or noise ▪ The progress bar plays to the end during video playback | O26: O | P26: X | Q26: X | R26: 주차 중 상시 녹화_지원 | S26: O
A27: OWP_035 | B27: ▪ Requirement-based test ▪ Test derived from field experience | C27: ▪ Requirements Analysis ▪ Field Experience-based Testing | D27: [Continuous Recording While Parked] Setting ON/OFF | E27: [Bad Conditions] Continuous Recording Setting Off While Parked Repeat Key ON/OFF quickly 20 times, then OFF | F27: ▪ Built-in Cam Boot Complete ▪ BLTN_CAM_State = 0x0 (BLTN_CAM Valid) ▪ BLTN_CAM_SD_Card_State = 0x0 (Good) ▪ Associated Controller CAN/Ethernet Communication Enabled ▪ Power: Key ON ▪ Voltage: 12V | G27: 1 | H27: ▪ Enter Built-in Cam Mode ▪ [Settings] - [Recording] - [Recording While Parked] - Turn Off Parking Continuous Recording, Turn Off Parking Event Recording ▪ (Vehicles with Motion Detection Recording while Parked) [Settings] - [Recording] - Turn Off Parking Motion Detection Recording Setting ▪ Quickly turn Key ON/OFF 20 times, then turn Key OFF (Real Vehicle Condition: Quickly press Engine Start button) ▪ Check Recording Status Signal (Verify that Continuous Recording while Parked has not been entered) | I27: ▪ BLTN_CAM_RecSta_OWP = 0x0(OFF) | J27: Pass | O27: X | P27: X | Q27: 02_OWP_013 | R27: 주차 중 상시 녹화_지원 | S27: O
G28: 2 | H28: ▪ Check front/rear camera indicator | I28: ▪ Camera Indicator OFF/-/Keep | O28: X | P28: X | Q28: △ | R28: 주차 중 상시 녹화_지원 | S28: O
G29: 3 | H29: ▪ Check event switch indicator | I29: ▪ Event switch indicator OFF/-/Hold | O29: X | P29: X | Q29: △ | R29: 주차 중 상시 녹화_지원 | S29: O
G30: 4 | H30: ▪ Check dark current | I30: ▪ Dark current must be 0.5mA or less | J30: Pass | O30: X | P30: X | Q30: 02_OWP_013 | R30: 주차 중 상시 녹화_지원 | S30: O
A31: OWP_003 | B31: ▪ Requirement-based test ▪ Test derived from field experience | C31: ▪ Requirements Analysis ▪ Field Experience-based Testing | D31: [Continuous Recording While Parked] : Full-time Recording | E31: Confirmation of recording file creation (20 hours) | F31: ▪ Built-in Cam Boot Complete ▪ BLTN_CAM_State = 0x0 (BLTN_CAM Valid) ▪ BLTN_CAM_SD_Card_State = 0x0 (Good) ▪ Associated Controller CAN/Ethernet Communication Enabled ▪ Power: Key ON ▪ Voltage: 12V ▪ Setting: Parking Continuous Recording ON | G31: 1 | H31: ▪ Enter Built-in Cam Mode ▪ [Advanced Settings] - [Continuous Recording Time While Parked] - Check signal after setting to 20 hours of recording | I31: ▪ BLTN_CAM_Set_PrkTime = 0x14(20h) | O31: X | P31: X | Q31: X | R31: 주차 중 상시 녹화_지원 | S31: O
G32: 2 | H32: ▪ Turn Key Off to enter continuous recording while parked ▪ 20-hour standby ▪ Turn Key ON, enter Built-in Cam mode, and check the parking continuous recording box | I32: ▪ Confirmation of continuous recording file saving while parked: Confirmation of creation of a list of 40 front & rear videos (30 minutes). | O32: X | P32: X | Q32: X | R32: 주차 중 상시 녹화_지원 | S32: O
A33: OWP_036 | B33: ▪ Requirement-based test ▪ Test derived from field experience | C33: ▪ Requirements Analysis ▪ Field Experience-based Testing | D33: [Continuous Recording While Parked] : Full-time Recording | E33: Check for interruption of related actions during continuous recording (20 hours) | F33: ▪ Built-in Cam Boot Complete ▪ BLTN_CAM_State = 0x0 (BLTN_CAM Valid) ▪ BLTN_CAM_SD_Card_State = 0x0 (Good) ▪ Associated Controller CAN/Ethernet Communication Enabled ▪ Power: Key ON ▪ Voltage: 12V ▪ Setting: Parking Continuous Recording ON | G33: 1 | H33: ▪ Enter Built-in Cam Mode ▪ [Advanced Settings] - [Continuous Recording Time While Parked] - Check signal after setting to 20 hours of recording | I33: ▪ BLTN_CAM_Set_PrkTime = 0x14(20h) | O33: X | P33: X | Q33: X | R33: 주차 중 상시 녹화_지원 | S33: O
G34: 2 | H34: ▪ Maintain CAN Alive status by sending NM_CGW_CCU message during 20-hour continuous parking recording ▪ Turn off the key to enter continuous parking recording ▪ Standby for 20 hours ▪ Check BLTN_CAM_RecSta_OWP signal in CAN LOG after continuous parking recording is complete | I34: ▪ The BLTN_CAM_RecSta_OWP signal will not be turned OFF at the time of individual file saving. | O34: X | P34: X | Q34: X | R34: 주차 중 상시 녹화_지원 | S34: O
A35: OWP_037 | B35: ▪ Requirement-based test ▪ Test derived from field experience | C35: ▪ Requirements Analysis ▪ Field Experience-based Testing | D35: [Continuous Recording While Parked] : Full-time Recording | E35: Confirmation of recording file creation (12 hours) | F35: ▪ Built-in Cam Boot Complete ▪ BLTN_CAM_State = 0x0 (BLTN_CAM Valid) ▪ BLTN_CAM_SD_Card_State = 0x0 (Good) ▪ Associated Controller CAN/Ethernet Communication Enabled ▪ Power: Key ON ▪ Voltage: 12V ▪ Setting: Parking Continuous Recording ON | G35: 1 | H35: ▪ Enter Built-in Cam Mode ▪ [Advanced Settings] - [Continuous Recording Time While Parked] - Check signal after setting to 12 hours of recording | I35: ▪ BLTN_CAM_Set_PrkTime = 0xC(12h) | O35: X | P35: X | Q35: X | R35: 주차 중 상시 녹화_지원 | S35: O
G36: 2 | H36: ▪ Turn Key Off to enter continuous recording while parked ▪ 12-hour standby ▪ Turn Key ON, enter Built-in Cam mode, and check the parking continuous recording box | I36: ▪ Confirmation of continuous recording file saving while parked: Confirmation of creation of a list of 24 front & rear videos (30 minutes). | O36: X | P36: X | Q36: X | R36: 주차 중 상시 녹화_지원 | S36: O
A37: OWP_038 | B37: ▪ Requirement-based test ▪ Test derived from field experience | C37: ▪ Requirements Analysis ▪ Field Experience-based Testing | D37: [Continuous Recording While Parked] : Full-time Recording | E37: Confirmation of recording file creation (6 hours) | F37: ▪ Built-in Cam Boot Complete ▪ BLTN_CAM_State = 0x0 (BLTN_CAM Valid) ▪ BLTN_CAM_SD_Card_State = 0x0 (Good) ▪ Associated Controller CAN/Ethernet Communication Enabled ▪ Power: Key ON ▪ Voltage: 12V ▪ Setting: Parking Continuous Recording ON | G37: 1 | H37: ▪ Enter Built-in Cam Mode ▪ [Advanced Settings] - [Continuous Recording Time While Parked] - Check signal after setting to 6 hours of recording | I37: ▪ BLTN_CAM_Set_PrkTime = 0x6(6h) | O37: X | P37: X | Q37: X | R37: 주차 중 상시 녹화_지원 | S37: O
G38: 2 | H38: ▪ Turn Key Off to enter continuous recording while parked ▪ Standby for 6 hours ▪ Turn Key ON, enter Built-in Cam mode, and check the parking continuous recording box | I38: ▪ Confirmation of continuous recording file saving while parked: Confirmation of creation of a list of 24 front & rear videos (30 minutes). | O38: X | P38: X | Q38: X | R38: 주차 중 상시 녹화_지원 | S38: O
A39: OWP_039 | B39: ▪ Requirement-based test ▪ Test derived from field experience | C39: ▪ Requirements Analysis ▪ Field Experience-based Testing | D39: [Continuous Recording While Parked] : Full-time Recording | E39: Confirmation of recording file creation (2 hours) | F39: ▪ Built-in Cam Boot Complete ▪ BLTN_CAM_State = 0x0 (BLTN_CAM Valid) ▪ BLTN_CAM_SD_Card_State = 0x0 (Good) ▪ Associated Controller CAN/Ethernet Communication Enabled ▪ Power: Key ON ▪ Voltage: 12V ▪ Setting: Parking Continuous Recording ON | G39: 1 | H39: ▪ Enter Built-in Cam Mode ▪ [Advanced Settings] - [Continuous Recording Time While Parked] - Set to 2 hours of recording and check the signal | I39: ▪ BLTN_CAM_Set_PrkTime = 0x2(2h) | O39: X | P39: X | Q39: X | R39: 주차 중 상시 녹화_지원 | S39: O
G40: 2 | H40: ▪ Enter Built-in Cam Mode ▪ Turn Key Off to enter continuous recording while parked ▪ Standby for 2 hours ▪ Turn Key ON, enter Built-in Cam Mode, and check the parking continuous recording box | I40: ▪ Confirmation of continuous recording file saving while parked: Confirmation of creation of 4 lists for front & rear video (30 minutes). | O40: X | P40: X | Q40: X | R40: 주차 중 상시 녹화_지원 | S40: O
...

Sheet HU 연동기능
A1: {="HU_"&TEXT(MAX(IFERROR(--MID($A$2:$A$4423,4,3),0)),"000")} -> HU_227 | D1: English Translation | E1: English Translation | F1: English Translation | H1: English Translation | I1: English Translation
A2: ID | B2: Test method | C2: TC design method | D2: Verification items | E2: detail | F2: Precondition | G2: Step | H2: Execution Procedure | I2: Expected value | J2: 결과 | K2: 측정값 | L2: 판정 | M2: 비고 | O2: 매뉴얼 기본 | P2: 자동화 기본 | Q2: 자동화 반영 | R2: 사양구분 | S2: 과거차문제
A3: [BLTN_CAM-기능-008] 시스템 설정
A4: HU_001 | B4: ▪ Requirement-based test ▪Test of interaction/ communication | C4: ▪ Requirements Analysis ▪Interface Analysis ▪State Transition Testing | D4: [Built-in Cam Screen Mode] (1) | E4: Built-in Cam Mode Video Output Confirmation | F4: ▪ Built-in Cam Boot Complete ▪ BLTN_CAM_State = 0x0 (BLTN_CAM Valid) ▪ BLTN_CAM_SD_Card_State = 0x0 (Good) ▪ Associated Controller CAN/Ethernet Communication Enabled ▪ Power: KEY ON ▪ Voltage: 12V | G4: 1 | H4: ▪ Enter HU Mode ▪ Enter Built-in Cam Mode (BLTN_CAM_LVDS_Mode_Cmd = 0x0:Front and Rear Camera) ▪ Touch Real-time Screen ▪ Go Back ▪ Confirm Repeat 10 times | I4: ▪ BLTN_CAM_LVDS_Mode_State = 0x0: Front and Rear Camera : LVDS video output switching time within 2 seconds (Approximately +1 second can be expected since CCNC generates the GUI) ▪ No black thumbnails in the video list | O4: X | P4: X | Q4: X
A5: HU_050 | B5: ▪ Requirement-based test ▪Test of interaction/ communication | C5: ▪ Requirements Analysis ▪Interface Analysis ▪State Transition Testing | D5: [Built-in Cam Screen Mode] (1) | E5: Check BLTN_CAM mode entry signal | F5: ▪ Built-in Cam Boot Complete ▪ BLTN_CAM_State = 0x0 (BLTN_CAM Valid) ▪ BLTN_CAM_SD_Card_State = 0x0 (Good) ▪ Associated Controller CAN/Ethernet Communication Enabled ▪ Power: KEY ON ▪ Voltage: 12V | G5: 1 | H5: ▪ Enter Built-In Cam Mode (HU_BLTN_CAM_UI_Mode = 0x1 : Built-In Cam Mode) | I5: ▪ BLTN_CAM_HU_UI_Mode (0x0: HU UI mode) → invalid → (0x2: Preparing BLTN_CAM Mode) → invalid → (0x1:BLTN_CAM mode) | J5: Pass | O5: O | P5: X | Q5: 03_HU_001
A6: HU_051 | B6: ▪ Requirement-based test ▪Test of interaction/ communication | C6: ▪ Requirements Analysis ▪Interface Analysis ▪State Transition Testing | D6: [Built-in Cam Screen Mode] (1) | E6: Transition to HU mode by turning the KEY OFF while in BLTN_CAM mode | F6: ▪ Built-in Cam Boot Complete ▪ BLTN_CAM_State = 0x0 (BLTN_CAM Valid) ▪ BLTN_CAM_SD_Card_State = 0x0 (Good) ▪ Associated Controller CAN/Ethernet Communication Enabled ▪ Power: KEY ON ▪ Voltage: 12V | G6: 1 | H6: ▪ KEY OFF while in Built-in Cam mode - Confirmation that BLTN_CAM_UI_Mode_Tmt_Req signal is not transmitted | I6: ▪ BLTN_CAM_HU_UI_Mode (0x1:BLTN_CAM mode) → invalid → (0x0: HU UI mode) → invalid → (0x0: HU UI mode) | J6: Pass | O6: X | P6: X | Q6: 03_HU_002
A7: HU_052 | B7: ▪ Requirement-based test ▪Test of interaction/ communication | C7: ▪ Requirements Analysis ▪Interface Analysis ▪State Transition Testing | D7: [Built-in Cam Screen Mode] (1) | E7: HU mode transition via HU mode Signal | F7: ▪ Built-in Cam Boot Complete ▪ BLTN_CAM_State = 0x0 (BLTN_CAM Valid) ▪ BLTN_CAM_SD_Card_State = 0x0 (Good) ▪ Associated Controller CAN/Ethernet Communication Enabled ▪ Power: KEY ON ▪ Voltage: 12V | G7: 1 | H7: ▪ Enter Built-in Cam Mode ▪ Touch Home/Back/CCNC Physical Buttons (HU_BLTN_CAM_UI_Mode = 0x0 : HU UI Mode) | I7: ▪ BLTN_CAM_HU_UI_Mode (0x1:BLTN_CAM mode) → invalid → (0x0: HU UI mode) | J7: Pass | O7: X | P7: X | Q7: 03_HU_003
A8: HU_053 | B8: ▪ Requirement-based test ▪Test of interaction/ communication | C8: ▪ Requirements Analysis ▪Interface Analysis ▪State Transition Testing | D8: [Built-in Cam Screen Mode] (1) | E8: HU mode ↔ BLTN_CAM mode | F8: ▪ Built-in Cam Boot Complete ▪ BLTN_CAM_State = 0x0 (BLTN_CAM Valid) ▪ BLTN_CAM_SD_Card_State = 0x0 (Good) ▪ Associated Controller CAN/Ethernet Communication Enabled ▪ Power: KEY ON ▪ Voltage: 12V ▪ Setting: Continuous Recording While Driving ON | G8: 1 | H8: ▪ Enter Built-in Cam Mode ▪ Touch the Home button (repeat quickly 10 times to confirm) | I8: ▪ When in HU mode after repeatedly entering and exiting Built-in Cam mode - BLTN_CAM_RecSta_OWD = 0x1 (Recording) | O8: X | P8: X | Q8: X
G9: 2 | H9: ▪ Enter Built-in Cam Mode ▪ Touch the Home button (repeat quickly 10 times to confirm) | I9: ▪ In Built-in Cam Mode: Do not record continuously while driving - BLTN_CAM_RecSta_OWD = 0x0 (OFF) ▪ No video distortion, green screen, black screen, or noise during recorded video playback | O9: X | P9: X | Q9: X
A10: HU_054 | B10: ▪ Requirement-based test ▪Test of interaction/ communication | C10: ▪ Requirements Analysis ▪Interface Analysis ▪State Transition Testing | D10: [Built-in Cam Screen Mode] (1) | E10: Exiting BLTN_CAM mode midway | F10: ▪ Built-in Cam Boot Complete ▪ BLTN_CAM_State = 0x0 (BLTN_CAM Valid) ▪ BLTN_CAM_SD_Card_State = 0x0 (Good) ▪ Associated Controller CAN/Ethernet Communication Enabled ▪ Power: KEY ON ▪ Voltage: 12V ▪ Setting: Continuous Recording While Driving ON | G10: 1 | H10: ▪ Touch the Built-in Cam Mode entry button ▪ Touch the HU Home button on the screen transition loading screen (confirm by repeating 10 times) | I10: ▪ Start continuous recording while driving immediately when repetitive action stops - BLTN_CAM_RecSta_OWD = 0x1 (Recording) | J10: Pass | O10: X | P10: X | Q10: 03_HU_004
A11: HU_055 | B11: ▪ Requirement-based test ▪Test of interaction/ communication | C11: ▪ Requirements Analysis ▪Interface Analysis ▪State Transition Testing | D11: [Built-in Cam Screen Mode] (1) | E11: Attempting to quickly enter built-in cam mode during boot-up | F11: ▪ Built-in Cam Boot Complete ▪ BLTN_CAM_State = 0x0 (BLTN_CAM Valid) ▪ BLTN_CAM_SD_Card_State = 0x0 (Good) ▪ Associated Controller CAN/Ethernet Communication Enabled ▪ Power: KEY ON ▪ Voltage: 12V ▪ Setting: Continuous Recording While Driving ON | G11: 1 | H11: ▪ KEY ON ▪ Repeatedly touch the Built-in Cam Mode Entry Button | I11: ▪ Enter Built-in Cam mode after boot is complete (enter within 2 seconds after boot is complete) ▪ BLTN_CAM_HU_UI_Mode = 0x1(BLTN_CAM mode) | J11: Pass | O11: X | P11: X | Q11: 03_HU_005
G12: 2 | H12: ▪ KEY ON ▪ Repeatedly touch the Built-in Cam Mode Entry Button | I12: ▪ Proceed with continuous recording while driving upon touching Back (1 second after exiting Built-in Cam mode) - BLTN_CAM_RecSta_OWD = 0x1 (Recording) | J12: Pass | O12: X | P12: X | Q12: 03_HU_005
A13: HU_056 | B13: ▪ Requirement-based test ▪Test of interaction/ communication | C13: ▪ Requirements Analysis ▪Interface Analysis ▪State Transition Testing | D13: [Built-in Cam Screen Mode] (1) | E13: Condition preventing entry into Built-in Cam mode: During booting | F13: ▪ Built-in Cam Boot Complete ▪ BLTN_CAM_State = 0x0 (BLTN_CAM Valid) ▪ BLTN_CAM_SD_Card_State = 0x0 (Good) ▪ Associated Controller CAN/Ethernet Communication Enabled ▪ Power: KEY ON ▪ Voltage: 12V ▪ Setting: Continuous Recording While Driving ON | G13: 1 | H13: ▪ Built-in Cam B+ Reset ▪ Built-in Cam Boot Complete | I13: ▪ Outputs 0xD until Built-in Cam boot is complete, 0x0 after completion ▪ BLTN_CAM_HU_UI_Mode invalid → (0xD : Built-in CAM not Ready to be HU UI Mode) → invalid → (0x0: HU UI mode) | M13: 과거차문제 PASTI-357 AR 내비 뷰 녹색 화면 출력 | O13: X | P13: X | Q13: X | S13: O
G14: 2 | H14: ▪ Built-in Cam boot complete ▪ Enter Built-in Cam mode | I14: ▪ Output 0x2 until built-in cam entry is complete, output 0x1 after completion ▪ BLTN_CAM_HU_UI_Mode (0x0: HU UI mode) → invalid → (0x2 : Preparing BLTN_CAM Mode) → invalid → (0x1:BLTN_CAM mode) | O14: X | P14: X | Q14: X | S14: O
